Workbook

Sheet CTZ 232-3 CENITH-SERENA SSC DES
C1: COTIZACION FT-CTZ-01
A2: FECHA: | B2: =TODAY() -> 46320 | G2: Nº CTZ | H2: 232- 03-26 | J2: REPOTENCIACION CIMBRA DE ALUMINIO WALL TIES_ PROTOTIPO VERONA_ CIMA SERENA_ PIEZAS A REEMPLAZAR PLANTA BAJA Y PLANTA ALTA
A3: PRODUCTO COTIZADO: | C3: CIMBRA DE ALUMINIO ROBUSTFORM 5.4 | J3: MOLDE DE ALUMINIO PARA UNA 1 VIVIENDA PROTOTIPO SERENA _ PLANTA BAJA + PLANTA ALTA + ESCALERA + PRETIL + SISTEMA DE ANDAMIAJE (COMPLETO)
A4: REFERENCIA | C4: REPOTENCIACION CIMBRA DE ALUMINIO TIPO MECCANO_ PROTOTIPO CENITH A SERENA_PLANTA BAJA + PLANTA ALTA + ESCALERA + PRETIL + SISTEMA DE ANDAMIAJE (COMPLETO)
A5: CLIENTE: | C5: FINCAMEX | M5: PRECIO | N5: 270
A6: PAIS / CIUDAD: | C6: MEXICO / CULIACAN
A7: CONTACTO: | C7: ING. HECTOR LIZARRAGA HEREDIA | G7: TELEFONO: | H7: hector.lizarraga@fincamex.com.mx
A9: COTIZACION CIMBRA PARA PLANTA BAJA
A10: CANT. | B10: UND MEDIDA | C10: CONCEPTO | G10: PRECIO/UNIT | H10: PRECIO | J10: PROGRAMA | K10: % AUMENTADO | M10: REPRESENTA | O10: TOTAL
A11: =O11 -> 142.78 | B11: MT2 | C11: EQUIPO PARA MUROS (PANELES ESTANDAR | G11: =N5 -> 270 | H11: =G11*A11 -> 38550.6 | J11: 129.8 | K11: 0.1 | M11: =J11*K11 -> 12.98 | O11: =J11+M11 -> 142.78
A12: =O12 -> 43.27335 | B12: MT2 | C12: EQUIPO PARA LOSA (3 JUEGOS LOSA PUNTAL) | G12: =N5 -> 270 | H12: =A12*G12 -> 11683.804 | J12: 37.629 | K12: 0.15 | M12: =J12*K12 -> 5.64435 | O12: =J12+M12 -> 43.27335
A13: =O13 -> 22.77 | B13: MT2 | C13: EQUIPO PARA CAPS Y EQL | G13: =N5 -> 270 | H13: =A13*G13 -> 6147.9 | J13: 20.7 | K13: 0.1 | M13: =J13*K13 -> 2.07 | O13: =J13+M13 -> 22.77 | Y13: =H16+H29+H36+H41+H46 -> 138130.98
A14: =O14 -> 41.8 | B14: MTL | C14: EQUIPO ANGULO DE ARRASTRE (2 plantas bajas) | G14: 25 | H14: =A14*G14 -> 1045 | J14: 38 | K14: =K11 -> 0.1 | M14: =J14*K14 -> 3.8 | O14: =J14+M14 -> 41.8 | Y14: =Y13+H19+H31 -> 87532.979
A15: INCLUYE ACCESORIOS BASICOS DE SUJECION: PASADORES, CUÑAS, CORBATAS, PUNTALES PARA VACIADO DEL MOLDE , TENSORES DE VANO, ESCALERA PARA ARMADO Y HERRAMIENTAS PARA ARMADO DE MOLDE
A16: =SUM(A11:A13) -> 208.82335 | B16: TOTAL MT2 | G16: SUBTOTAL | H16: =SUM(H11:H15) -> 57427.304
A17: =SUM(A14) -> 41.8 | B17: TOTAL ML | M17: 208.82 | N17: =M17*45% -> 93.969
N18: =M17*55% -> 114.851
A19: -93.9 | B19: MT2 | C19: EQUIPO ADAPTADO DE INVENTARIO EXISTENTE MECCANO MOLDE CENITH PLANTA BAJA | G19: =N5 -> 270 | H19: =G19*A19 -> -25353 | Y19: pb | Z19: =A11+A12+A13 -> 208.82335 | AA19: =Z19+A19 -> 114.92335
A21: =A16+A19 -> 114.92335 | B21: TOTAL MT2 | C21: VALOR TOTAL EQUIPO ALUMINIO PLANTA BAJA | H21: =H16+H19 -> 32074.304 | K21: =A21*G19 -> 31029.304
A23: COTIZACION CIMBRA PARA PLANTA ALTA
A24: CANT. | B24: UND MEDIDA | C24: CONCEPTO | G24: PRECIO/UNIT | H24: PRECIO
A25: =O25 -> 163.031 | B25: MT2 | C25: EQUIPO PARA MUROS (PANELES ESTANDAR) Y CAPS | G25: =N5 -> 270 | H25: =G25*A25 -> 44018.37 | J25: 148.21 | K25: =K11 -> 0.1 | M25: =J25*K25 -> 14.821 | O25: =J25+M25 -> 163.031
A26: =O26 -> 44.62 | B26: MT2 | C26: EQUIPO PARA LOSA (3 JUEGOS LOSA PUNTAL) | G26: =N5 -> 270 | H26: =G26*A26 -> 12047.4 | J26: 38.8 | K26: =K12 -> 0.15 | M26: =J26*K26 -> 5.82 | O26: =J26+M26 -> 44.62
A27: =O27 -> 39.05 | B27: MT2 | C27: EQUIPO PARA CULATAS (PENDIENTES PARA INCLINACION 2%) | G27: =N5 -> 270 | H27: =G27*A27 -> 10543.5 | J27: 35.5 | K27: =K13 -> 0.1 | M27: =J27*K27 -> 3.55 | O27: =J27+M27 -> 39.05
A28: INCLUYE ACCESORIOS BASICOS DE SUJECION: PASADORES, CUÑAS, CORBATAS, PUNTALES PARA VACIADO DEL MOLDE , TENSORES DE VANO, ESCALERA PARA ARMADO Y HERRAMIENTAS PARA ARMADO DE MOLDE
A29: =A25+A26+A27 -> 246.701 | B29: TOTAL MT2 | G29: SUBTOTAL | H29: =SUM(H25:H28) -> 66609.27
A31: -93.5 | B31: MT2 | C31: EQUIPO ADAPTADO DE INVENTARIO EXISTENTE MECCANO MOLDE CENITH PLANTA ALTA | G31: =N5 -> 270 | H31: =G31*A31 -> -25245 | J31: =A25+A26 -> 207.651 | K31: =J31*45% -> 93.44295 | X31: =A29+A31 -> 153.201 | Z31: =A25+A26+A27 -> 246.701
A33: COTIZACION CIMBRA PARA PRETIL | K33: =J31*55% -> 114.20805 | Q33: =H29+H31 -> 41364.27 | Z33: =Z31+A31 -> 153.201 | AC33: =H29+H31 -> 41364.27
A34: CANT. | B34: UND MEDIDA | C34: CONCEPTO | G34: PRECIO/UNIT | H34: PRECIO | Q34: =Q33+H36+H41+H46 -> 55458.675 | X34: =A21 -> 114.92335 | AC34: =AC33+H36+H41+H46 -> 55458.675
A35: =O35 -> 12.627 | B35: MT2 | C35: EQUIPO DE CIMBRA DE ALUMINIO PRETILES AZOTEA | G35: =N5 -> 270 | H35: =G35*A35 -> 3409.29 | J35: 10.98 | K35: =K26 -> 0.15 | M35: =J35*K35 -> 1.647 | O35: =J35+M35 -> 12.627
A36: =SUM(A35:A35) -> 12.627 | B36: TOTAL MT2 | G36: SUBTOTAL | H36: =SUM(H35:H35) -> 3409.29
Z37: =Z33+AA19 -> 268.12435
A38: COTIZACION CIMBRA PARA ESCALERA | AC38: =AC34+H21 -> 87532.98
A39: CANT. | B39: UND MEDIDA | C39: CONCEPTO | G39: PRECIO/UNIT | H39: PRECIO | Z39: =A36+A46 -> 23.7015
A40: =O40 -> 28.5 | B40: MT2 | C40: EQUIPO PARA CIMBRA DE UNA (1) ESCALERAS IZQ Y DERECHA PARA COLADO MONOLOTICO INTEGRADO A PAREDES | G40: 270 | H40: =G40*A40 -> 7695 | J40: 19 | K40: 0.5 | M40: =J40*K40 -> 9.5 | O40: =J40+M40 -> 28.5
A41: =SUM(A40:A40) -> 28.5 | B41: TOTAL MT2 | G41: SUBTOTAL | H41: =SUM(H40:H40) -> 7695 | Z41: 28.5
A43: COTIZACION CIMBRA PARA REBORDE DE FACHADA | Z43: =Z37+Z39+Z41 -> 320.32585 | AA43: 270 | AB43: =(Z43*AA43)+H14 -> 87532.98
A44: CANT. | B44: UND MEDIDA | C44: CONCEPTO | G44: PRECIO/UNIT | H44: PRECIO
A45: =O45 -> 11.0745 | B45: MT2 | C45: EQUIPO DE CIMBRA DE ALUMINIO REBORDE DE FACHADA | G45: =N5 -> 270 | H45: =G45*A45 -> 2990.115 | J45: 9.63 | K45: =K35 -> 0.15 | M45: =J45*K45 -> 1.4445 | O45: =J45+M45 -> 11.0745
A46: =SUM(A45:A45) -> 11.0745 | B46: TOTAL MT2 | G46: SUBTOTAL | H46: =SUM(H45:H45) -> 2990.115
...

Sheet CTZ 232-1 USD SERENA SSCOMP (26
D1: COTIZACION FT-CTZ-01
B2: FECHA: | C2: =TODAY() -> 46320 | H2: Nº CTZ | I2: 232- 01-26
B3: PRODUCTO COTIZADO: | D3: CIMBRA DE ALUMINIO ROBUSTFORM 5.4
B4: REFERENCIA | D4: MOLDE DE ALUMINIO PARA UNA 1 VIVIENDA PROTOTIPO SERENA _ PLANTA BAJA + PLANTA ALTA + ESCALERA + PRETIL + SISTEMA DE ANDAMIAJE (COMPLETO)
B5: CLIENTE: | D5: FINCAMEX | N5: PRECIO | O5: 270
B6: PAIS / CIUDAD: | D6: MEXICO / CULIACAN
B7: CONTACTO: | D7: ING. HECTOR LIZARRAGA HEREDIA | H7: TELEFONO: | I7: hector.lizarraga@fincamex.com.mx
B9: COTIZACION CIMBRA PARA PLANTA BAJA
B10: CANT. | C10: UND MEDIDA | D10: CONCEPTO | H10: PRECIO/UNIT | I10: PRECIO | K10: PROGRAMA | L10: % AUMENTADO | N10: REPRESENTA | P10: TOTAL
B11: =P11 -> 142.78 | C11: MT2 | D11: EQUIPO PARA MUROS (PANELES ESTANDAR | H11: =O5 -> 270 | I11: =H11*B11 -> 38550.6 | K11: 129.8 | L11: 0.1 | N11: =K11*L11 -> 12.98 | P11: =K11+N11 -> 142.78
B12: =P12 -> 43.27335 | C12: MT2 | D12: EQUIPO PARA LOSA (3 JUEGOS LOSA PUNTAL) | H12: =O5 -> 270 | I12: =B12*H12 -> 11683.804 | K12: 37.629 | L12: 0.15 | N12: =K12*L12 -> 5.64435 | P12: =K12+N12 -> 43.27335
B13: =P13 -> 22.77 | C13: MT2 | D13: EQUIPO PARA CAPS Y EQL | H13: =O5 -> 270 | I13: =B13*H13 -> 6147.9 | K13: 20.7 | L13: 0.1 | N13: =K13*L13 -> 2.07 | P13: =K13+N13 -> 22.77
B14: =P14 -> 41.8 | C14: MTL | D14: EQUIPO ANGULO DE ARRASTRE (2 plantas bajas) | H14: 25 | I14: =B14*H14 -> 1045 | K14: 38 | L14: =L11 -> 0.1 | N14: =K14*L14 -> 3.8 | P14: =K14+N14 -> 41.8
B15: INCLUYE ACCESORIOS BASICOS DE SUJECION: PASADORES, CUÑAS, CORBATAS, PUNTALES PARA VACIADO DEL MOLDE , TENSORES DE VANO, ESCALERA PARA ARMADO Y HERRAMIENTAS PARA ARMADO DE MOLDE
B16: =SUM(B11:B13) -> 208.82335 | C16: TOTAL MT2 | H16: SUBTOTAL | I16: =SUM(I11:I15) -> 57427.304
B17: =SUM(B14) -> 41.8 | C17: TOTAL ML
B19: COTIZACION CIMBRA PARA PLANTA ALTA
B20: CANT. | C20: UND MEDIDA | D20: CONCEPTO | H20: PRECIO/UNIT | I20: PRECIO
B21: =P21 -> 163.031 | C21: MT2 | D21: EQUIPO PARA MUROS (PANELES ESTANDAR) Y CAPS | H21: =O5 -> 270 | I21: =H21*B21 -> 44018.37 | K21: 148.21 | L21: =L11 -> 0.1 | N21: =K21*L21 -> 14.821 | P21: =K21+N21 -> 163.031
B22: =P22 -> 44.62 | C22: MT2 | D22: EQUIPO PARA LOSA (3 JUEGOS LOSA PUNTAL) | H22: =O5 -> 270 | I22: =H22*B22 -> 12047.4 | K22: 38.8 | L22: =L12 -> 0.15 | N22: =K22*L22 -> 5.82 | P22: =K22+N22 -> 44.62
B23: =P23 -> 39.05 | C23: MT2 | D23: EQUIPO PARA CULATAS (PENDIENTES PARA INCLINACION 2%) | H23: =O5 -> 270 | I23: =H23*B23 -> 10543.5 | K23: 35.5 | L23: =L13 -> 0.1 | N23: =K23*L23 -> 3.55 | P23: =K23+N23 -> 39.05
B24: INCLUYE ACCESORIOS BASICOS DE SUJECION: PASADORES, CUÑAS, CORBATAS, PUNTALES PARA VACIADO DEL MOLDE , TENSORES DE VANO, ESCALERA PARA ARMADO Y HERRAMIENTAS PARA ARMADO DE MOLDE
B25: =SUM(B21:B24) -> 246.701 | C25: TOTAL MT2 | H25: SUBTOTAL | I25: =SUM(I21:I24) -> 66609.27
B27: COTIZACION CIMBRA PARA PRETIL
B28: CANT. | C28: UND MEDIDA | D28: CONCEPTO | H28: PRECIO/UNIT | I28: PRECIO
B29: =P29 -> 12.627 | C29: MT2 | D29: EQUIPO DE CIMBRA DE ALUMINIO PRETILES AZOTEA | H29: =O5 -> 270 | I29: =H29*B29 -> 3409.29 | K29: 10.98 | L29: =L22 -> 0.15 | N29: =K29*L29 -> 1.647 | P29: =K29+N29 -> 12.627
B30: =SUM(B29:B29) -> 12.627 | C30: TOTAL MT2 | H30: SUBTOTAL | I30: =SUM(I29:I29) -> 3409.29
B32: COTIZACION CIMBRA PARA ESCALERA
B33: CANT. | C33: UND MEDIDA | D33: CONCEPTO | H33: PRECIO/UNIT | I33: PRECIO
B34: =P34 -> 28.5 | C34: MT2 | D34: EQUIPO PARA CIMBRA DE UNA (1) ESCALERAS IZQ Y DERECHA PARA COLADO MONOLOTICO INTEGRADO A PAREDES | H34: 270 | I34: =H34*B34 -> 7695 | K34: 19 | L34: 0.5 | N34: =K34*L34 -> 9.5 | P34: =K34+N34 -> 28.5
B35: =SUM(B34:B34) -> 28.5 | C35: TOTAL MT2 | H35: SUBTOTAL | I35: =SUM(I34:I34) -> 7695
B37: COTIZACION CIMBRA PARA REBORDE DE FACHADA
B38: CANT. | C38: UND MEDIDA | D38: CONCEPTO | H38: PRECIO/UNIT | I38: PRECIO
B39: =P39 -> 11.0745 | C39: MT2 | D39: EQUIPO DE CIMBRA DE ALUMINIO REBORDE DE FACHADA | H39: =O5 -> 270 | I39: =H39*B39 -> 2990.115 | K39: 9.63 | L39: =L29 -> 0.15 | N39: =K39*L39 -> 1.4445 | P39: =K39+N39 -> 11.0745
B40: =SUM(B39:B39) -> 11.0745 | C40: TOTAL MT2 | H40: SUBTOTAL | I40: =SUM(I39:I39) -> 2990.115
B42: =B35+B30+B25+B16+B40 -> 507.72585 | C42: TOTAL MT2 | D42: VALOR TOTAL EQUIPO ALUMINIO | I42: =I16+I25+I30+I35+I40 -> 138130.98
B44: COMPLEMENTARIOS
B45: CANT. | C45: UND MEDIDA | D45: CONCEPTO | H45: PRECIO/UNIT | I45: PRECIO
B46: 70 | C46: MTL | D46: SISTEMA DE ANDAMIAJE, 2 (DOS) PERIMETROS DE LA VIVIENDA INCLUYE: ( PASARELAS, PASRELAS DINTEL, PLATAFORMAS LAMINA ANTIRRAPANTE, GUARDA CUERPO DOBLE TUBO RIEL, ACCESORIOS DE SUJECION) (COMPLETO) | H46: 360 | I46: =B46*H46 -> 25200
B47: 35 | C47: MTL | D47: EQUIPO DE SEGURIDAD PARA EL COLADO (GUARDA CUERPO), 1 (UN) PERIMETRO DEL MOLDE INCLUYE: ALINEADORES DE CAP, JUEGO DE GUARDA CUERPOS DE DOBLE TUBO RIEL, ACCESORIOS DE SUJECCION (COMPLETO) | H47: 180 | I47: =B47*H47 -> 6300
...

Sheet CTZ 232-2 USD SERENA SSBASI (26
D1: COTIZACION FT-CTZ-01
B2: FECHA: | C2: =TODAY() -> 46320 | H2: Nº CTZ | I2: 232- 02-25
B3: PRODUCTO COTIZADO: | D3: CIMBRA DE ALUMINIO ROBUSTFORM 5.4
B4: REFERENCIA | D4: MOLDE DE ALUMINIO PARA UNA 1 VIVIENDA PROTOTIPO SERENA _ PLANTA BAJA + PLANTA ALTA + ESCALERA + PRETIL + SISTEMA DE ANDAMIAJE (BASICO)
B5: CLIENTE: | D5: FINCAMEX | N5: PRECIO | O5: 270
B6: PAIS / CIUDAD: | D6: MEXICO / CULIACAN
B7: CONTACTO: | D7: ING. HECTOR LIZARRAGA HEREDIA | H7: TELEFONO: | I7: hector.lizarraga@fincamex.com.mx
B9: COTIZACION CIMBRA PARA PLANTA BAJA
B10: CANT. | C10: UND MEDIDA | D10: CONCEPTO | H10: PRECIO/UNIT | I10: PRECIO | K10: PROGRAMA | L10: % AUMENTADO | N10: REPRESENTA | P10: TOTAL
B11: =P11 -> 142.78 | C11: MT2 | D11: EQUIPO PARA MUROS (PANELES ESTANDAR | H11: =O5 -> 270 | I11: =H11*B11 -> 38550.6 | K11: 129.8 | L11: 0.1 | N11: =K11*L11 -> 12.98 | P11: =K11+N11 -> 142.78
B12: =P12 -> 43.27335 | C12: MT2 | D12: EQUIPO PARA LOSA (3 JUEGOS LOSA PUNTAL) | H12: =O5 -> 270 | I12: =B12*H12 -> 11683.804 | K12: 37.629 | L12: 0.15 | N12: =K12*L12 -> 5.64435 | P12: =K12+N12 -> 43.27335
B13: =P13 -> 22.77 | C13: MT2 | D13: EQUIPO PARA CAPS Y EQL | H13: =O5 -> 270 | I13: =B13*H13 -> 6147.9 | K13: 20.7 | L13: 0.1 | N13: =K13*L13 -> 2.07 | P13: =K13+N13 -> 22.77
B14: =P14 -> 41.8 | C14: MTL | D14: EQUIPO ANGULO DE ARRASTRE (2 plantas bajas) | H14: 25 | I14: =B14*H14 -> 1045 | K14: 38 | L14: =L11 -> 0.1 | N14: =K14*L14 -> 3.8 | P14: =K14+N14 -> 41.8
B15: INCLUYE ACCESORIOS BASICOS DE SUJECION: PASADORES, CUÑAS, CORBATAS, PUNTALES PARA VACIADO DEL MOLDE , TENSORES DE VANO, ESCALERA PARA ARMADO Y HERRAMIENTAS PARA ARMADO DE MOLDE
B16: =SUM(B11:B13) -> 208.82335 | C16: TOTAL MT2 | H16: SUBTOTAL | I16: =SUM(I11:I15) -> 57427.304
B17: =SUM(B14) -> 41.8 | C17: TOTAL ML
B19: COTIZACION CIMBRA PARA PLANTA ALTA
B20: CANT. | C20: UND MEDIDA | D20: CONCEPTO | H20: PRECIO/UNIT | I20: PRECIO
B21: =P21 -> 163.031 | C21: MT2 | D21: EQUIPO PARA MUROS (PANELES ESTANDAR) Y CAPS | H21: =O5 -> 270 | I21: =H21*B21 -> 44018.37 | K21: 148.21 | L21: =L11 -> 0.1 | N21: =K21*L21 -> 14.821 | P21: =K21+N21 -> 163.031
B22: =P22 -> 44.62 | C22: MT2 | D22: EQUIPO PARA LOSA (3 JUEGOS LOSA PUNTAL) | H22: =O5 -> 270 | I22: =H22*B22 -> 12047.4 | K22: 38.8 | L22: =L12 -> 0.15 | N22: =K22*L22 -> 5.82 | P22: =K22+N22 -> 44.62
B23: =P23 -> 39.05 | C23: MT2 | D23: EQUIPO PARA CULATAS (PENDIENTES PARA INCLINACION 2%) | H23: =O5 -> 270 | I23: =H23*B23 -> 10543.5 | K23: 35.5 | L23: =L13 -> 0.1 | N23: =K23*L23 -> 3.55 | P23: =K23+N23 -> 39.05
B24: INCLUYE ACCESORIOS BASICOS DE SUJECION: PASADORES, CUÑAS, CORBATAS, PUNTALES PARA VACIADO DEL MOLDE , TENSORES DE VANO, ESCALERA PARA ARMADO Y HERRAMIENTAS PARA ARMADO DE MOLDE
B25: =SUM(B21:B24) -> 246.701 | C25: TOTAL MT2 | H25: SUBTOTAL | I25: =SUM(I21:I24) -> 66609.27
B27: COTIZACION CIMBRA PARA PRETIL
B28: CANT. | C28: UND MEDIDA | D28: CONCEPTO | H28: PRECIO/UNIT | I28: PRECIO
B29: =P29 -> 12.627 | C29: MT2 | D29: EQUIPO DE CIMBRA DE ALUMINIO PRETILES AZOTEA | H29: =O5 -> 270 | I29: =H29*B29 -> 3409.29 | K29: 10.98 | L29: =L22 -> 0.15 | N29: =K29*L29 -> 1.647 | P29: =K29+N29 -> 12.627
B30: =SUM(B29:B29) -> 12.627 | C30: TOTAL MT2 | H30: SUBTOTAL | I30: =SUM(I29:I29) -> 3409.29
B32: COTIZACION CIMBRA PARA ESCALERA
B33: CANT. | C33: UND MEDIDA | D33: CONCEPTO | H33: PRECIO/UNIT | I33: PRECIO
B34: =P34 -> 28.5 | C34: MT2 | D34: EQUIPO PARA CIMBRA DE UNA (1) ESCALERAS IZQ Y DERECHA PARA COLADO MONOLOTICO INTEGRADO A PAREDES | H34: 270 | I34: =H34*B34 -> 7695 | K34: 19 | L34: 0.5 | N34: =K34*L34 -> 9.5 | P34: =K34+N34 -> 28.5
B35: =SUM(B34:B34) -> 28.5 | C35: TOTAL MT2 | H35: SUBTOTAL | I35: =SUM(I34:I34) -> 7695
B37: COTIZACION CIMBRA PARA REBORDE DE FACHADA
B38: CANT. | C38: UND MEDIDA | D38: CONCEPTO | H38: PRECIO/UNIT | I38: PRECIO
B39: =P39 -> 11.0745 | C39: MT2 | D39: EQUIPO DE CIMBRA DE ALUMINIO REBORDE DE FACHADA | H39: =O5 -> 270 | I39: =H39*B39 -> 2990.115 | K39: 9.63 | L39: =L29 -> 0.15 | N39: =K39*L39 -> 1.4445 | P39: =K39+N39 -> 11.0745
B40: =SUM(B39:B39) -> 11.0745 | C40: TOTAL MT2 | H40: SUBTOTAL | I40: =SUM(I39:I39) -> 2990.115
B42: =B35+B30+B25+B16+B40 -> 507.72585 | C42: TOTAL MT2 | D42: VALOR TOTAL EQUIPO ALUMINIO | I42: =I16+I25+I30+I35+I40 -> 138130.98
B44: COMPLEMENTARIOS
B45: CANT. | C45: UND MEDIDA | D45: CONCEPTO | H45: PRECIO/UNIT | I45: PRECIO
B46: 70 | C46: MTL | D46: SISTEMA DE ANDAMIAJE, 2 (DOS) PERIMETROS DE LA VIVIENDA INCLUYE: ( PASARELAS, PASRELAS DINTEL, ACCESORIOS DE SUJECION) (BASICO) | H46: 120 | I46: =B46*H46 -> 8400
B47: 35 | C47: MTL | D47: EQUIPO DE SEGURIDAD PARA EL COLADO (GUARDA CUERPO), 1 (UN) PERIMETRO DEL MOLDE INCLUYE: ALINEADORES DE CAP, ACCESORIOS DE SUJECCION (BASICO) | H47: 60 | I47: =B47*H47 -> 2100
...

Sheet CTZ 232-3 CENITH-SERENA SSC(26)
C1: COTIZACION FT-CTZ-01
A2: FECHA: | B2: =TODAY() -> 46320 | G2: Nº CTZ | H2: 232- 03-26 | J2: REPOTENCIACION CIMBRA DE ALUMINIO WALL TIES_ PROTOTIPO VERONA_ CIMA SERENA_ PIEZAS A REEMPLAZAR PLANTA BAJA Y PLANTA ALTA
A3: PRODUCTO COTIZADO: | C3: CIMBRA DE ALUMINIO ROBUSTFORM 5.4 | J3: MOLDE DE ALUMINIO PARA UNA 1 VIVIENDA PROTOTIPO SERENA _ PLANTA BAJA + PLANTA ALTA + ESCALERA + PRETIL + SISTEMA DE ANDAMIAJE (COMPLETO)
A4: REFERENCIA | C4: REPOTENCIACION CIMBRA DE ALUMINIO TIPO MECCANO_ PROTOTIPO CENITH A SERENA_PLANTA BAJA + PLANTA ALTA + ESCALERA + PRETIL + SISTEMA DE ANDAMIAJE (COMPLETO)
A5: CLIENTE: | C5: FINCAMEX | M5: PRECIO | N5: 270
A6: PAIS / CIUDAD: | C6: MEXICO / CULIACAN
A7: CONTACTO: | C7: ING. HECTOR LIZARRAGA HEREDIA | G7: TELEFONO: | H7: hector.lizarraga@fincamex.com.mx
A9: COTIZACION CIMBRA PARA PLANTA BAJA
A10: CANT. | B10: UND MEDIDA | C10: CONCEPTO | G10: PRECIO/UNIT | H10: PRECIO | J10: PROGRAMA | K10: % AUMENTADO | M10: REPRESENTA | O10: TOTAL
A11: =O11 -> 142.78 | B11: MT2 | C11: EQUIPO PARA MUROS (PANELES ESTANDAR | G11: =N5 -> 270 | H11: =G11*A11 -> 38550.6 | J11: 129.8 | K11: 0.1 | M11: =J11*K11 -> 12.98 | O11: =J11+M11 -> 142.78
A12: =O12 -> 43.27335 | B12: MT2 | C12: EQUIPO PARA LOSA (3 JUEGOS LOSA PUNTAL) | G12: =N5 -> 270 | H12: =A12*G12 -> 11683.804 | J12: 37.629 | K12: 0.15 | M12: =J12*K12 -> 5.64435 | O12: =J12+M12 -> 43.27335
A13: =O13 -> 22.77 | B13: MT2 | C13: EQUIPO PARA CAPS Y EQL | G13: =N5 -> 270 | H13: =A13*G13 -> 6147.9 | J13: 20.7 | K13: 0.1 | M13: =J13*K13 -> 2.07 | O13: =J13+M13 -> 22.77 | Y13: =H16+H29+H36+H41+H46 -> 138130.98
A14: =O14 -> 41.8 | B14: MTL | C14: EQUIPO ANGULO DE ARRASTRE (2 plantas bajas) | G14: 25 | H14: =A14*G14 -> 1045 | J14: 38 | K14: =K11 -> 0.1 | M14: =J14*K14 -> 3.8 | O14: =J14+M14 -> 41.8 | Y14: =Y13+H19+H31 -> 87532.979
A15: INCLUYE ACCESORIOS BASICOS DE SUJECION: PASADORES, CUÑAS, CORBATAS, PUNTALES PARA VACIADO DEL MOLDE , TENSORES DE VANO, ESCALERA PARA ARMADO Y HERRAMIENTAS PARA ARMADO DE MOLDE
A16: =SUM(A11:A13) -> 208.82335 | B16: TOTAL MT2 | G16: SUBTOTAL | H16: =SUM(H11:H15) -> 57427.304
A17: =SUM(A14) -> 41.8 | B17: TOTAL ML | M17: 208.82 | N17: =M17*45% -> 93.969
N18: =M17*55% -> 114.851
A19: -93.9 | B19: MT2 | C19: EQUIPO ADAPTADO DE INVENTARIO EXISTENTE MECCANO MOLDE CENITH PLANTA BAJA | G19: =N5 -> 270 | H19: =G19*A19 -> -25353 | Y19: pb | Z19: =A11+A12+A13 -> 208.82335 | AA19: =Z19+A19 -> 114.92335
A21: =A16+A19 -> 114.92335 | B21: TOTAL MT2 | C21: VALOR TOTAL EQUIPO ALUMINIO PLANTA BAJA | H21: =H16+H19 -> 32074.304 | K21: =A21*G19 -> 31029.304
A23: COTIZACION CIMBRA PARA PLANTA ALTA
A24: CANT. | B24: UND MEDIDA | C24: CONCEPTO | G24: PRECIO/UNIT | H24: PRECIO
A25: =O25 -> 163.031 | B25: MT2 | C25: EQUIPO PARA MUROS (PANELES ESTANDAR) Y CAPS | G25: =N5 -> 270 | H25: =G25*A25 -> 44018.37 | J25: 148.21 | K25: =K11 -> 0.1 | M25: =J25*K25 -> 14.821 | O25: =J25+M25 -> 163.031
A26: =O26 -> 44.62 | B26: MT2 | C26: EQUIPO PARA LOSA (3 JUEGOS LOSA PUNTAL) | G26: =N5 -> 270 | H26: =G26*A26 -> 12047.4 | J26: 38.8 | K26: =K12 -> 0.15 | M26: =J26*K26 -> 5.82 | O26: =J26+M26 -> 44.62
A27: =O27 -> 39.05 | B27: MT2 | C27: EQUIPO PARA CULATAS (PENDIENTES PARA INCLINACION 2%) | G27: =N5 -> 270 | H27: =G27*A27 -> 10543.5 | J27: 35.5 | K27: =K13 -> 0.1 | M27: =J27*K27 -> 3.55 | O27: =J27+M27 -> 39.05
A28: INCLUYE ACCESORIOS BASICOS DE SUJECION: PASADORES, CUÑAS, CORBATAS, PUNTALES PARA VACIADO DEL MOLDE , TENSORES DE VANO, ESCALERA PARA ARMADO Y HERRAMIENTAS PARA ARMADO DE MOLDE
A29: =A25+A26+A27 -> 246.701 | B29: TOTAL MT2 | G29: SUBTOTAL | H29: =SUM(H25:H28) -> 66609.27
A31: -93.5 | B31: MT2 | C31: EQUIPO ADAPTADO DE INVENTARIO EXISTENTE MECCANO MOLDE CENITH PLANTA ALTA | G31: =N5 -> 270 | H31: =G31*A31 -> -25245 | J31: =A25+A26 -> 207.651 | K31: =J31*45% -> 93.44295 | X31: =A29+A31 -> 153.201 | Z31: =A25+A26+A27 -> 246.701
A33: COTIZACION CIMBRA PARA PRETIL | K33: =J31*55% -> 114.20805 | Q33: =H29+H31 -> 41364.27 | Z33: =Z31+A31 -> 153.201 | AC33: =H29+H31 -> 41364.27
A34: CANT. | B34: UND MEDIDA | C34: CONCEPTO | G34: PRECIO/UNIT | H34: PRECIO | Q34: =Q33+H36+H41+H46 -> 55458.675 | X34: =A21 -> 114.92335 | AC34: =AC33+H36+H41+H46 -> 55458.675
A35: =O35 -> 12.627 | B35: MT2 | C35: EQUIPO DE CIMBRA DE ALUMINIO PRETILES AZOTEA | G35: =N5 -> 270 | H35: =G35*A35 -> 3409.29 | J35: 10.98 | K35: =K26 -> 0.15 | M35: =J35*K35 -> 1.647 | O35: =J35+M35 -> 12.627
A36: =SUM(A35:A35) -> 12.627 | B36: TOTAL MT2 | G36: SUBTOTAL | H36: =SUM(H35:H35) -> 3409.29
Z37: =Z33+AA19 -> 268.12435
A38: COTIZACION CIMBRA PARA ESCALERA | AC38: =AC34+H21 -> 87532.98
A39: CANT. | B39: UND MEDIDA | C39: CONCEPTO | G39: PRECIO/UNIT | H39: PRECIO | Z39: =A36+A46 -> 23.7015
A40: =O40 -> 28.5 | B40: MT2 | C40: EQUIPO PARA CIMBRA DE UNA (1) ESCALERAS IZQ Y DERECHA PARA COLADO MONOLOTICO INTEGRADO A PAREDES | G40: 270 | H40: =G40*A40 -> 7695 | J40: 19 | K40: 0.5 | M40: =J40*K40 -> 9.5 | O40: =J40+M40 -> 28.5
A41: =SUM(A40:A40) -> 28.5 | B41: TOTAL MT2 | G41: SUBTOTAL | H41: =SUM(H40:H40) -> 7695 | Z41: 28.5
A43: COTIZACION CIMBRA PARA REBORDE DE FACHADA | Z43: =Z37+Z39+Z41 -> 320.32585 | AA43: 270 | AB43: =(Z43*AA43)+H14 -> 87532.98
A44: CANT. | B44: UND MEDIDA | C44: CONCEPTO | G44: PRECIO/UNIT | H44: PRECIO
A45: =O45 -> 11.0745 | B45: MT2 | C45: EQUIPO DE CIMBRA DE ALUMINIO REBORDE DE FACHADA | G45: =N5 -> 270 | H45: =G45*A45 -> 2990.115 | J45: 9.63 | K45: =K35 -> 0.15 | M45: =J45*K45 -> 1.4445 | O45: =J45+M45 -> 11.0745
A46: =SUM(A45:A45) -> 11.0745 | B46: TOTAL MT2 | G46: SUBTOTAL | H46: =SUM(H45:H45) -> 2990.115
...

Sheet CTZ 232-5 athali-SERENA SSC(26)
C1: COTIZACION FT-CTZ-01
A2: FECHA: | B2: =TODAY() -> 46320 | G2: Nº CTZ | H2: 232- 05-26 | J2: REPOTENCIACION CIMBRA DE ALUMINIO WALL TIES_ PROTOTIPO VERONA_ CIMA SERENA_ PIEZAS A REEMPLAZAR PLANTA BAJA Y PLANTA ALTA
A3: PRODUCTO COTIZADO: | C3: CIMBRA DE ALUMINIO ROBUSTFORM 5.4 | J3: MOLDE DE ALUMINIO PARA UNA 1 VIVIENDA PROTOTIPO SERENA _ PLANTA BAJA + PLANTA ALTA + ESCALERA + PRETIL + SISTEMA DE ANDAMIAJE (COMPLETO)
A4: REFERENCIA | C4: REPOTENCIACION CIMBRA DE ALUMINIO TIPO CMR_ PROTOTIPO ATTALIA A SERENA_PLANTA BAJA + PLANTA ALTA + ESCALERA + PRETIL + SISTEMA DE ANDAMIAJE (COMPLETO)
A5: CLIENTE: | C5: FINCAMEX | M5: PRECIO | N5: 270
A6: PAIS / CIUDAD: | C6: MEXICO / CULIACAN
A7: CONTACTO: | C7: ING. HECTOR LIZARRAGA HEREDIA | G7: TELEFONO: | H7: hector.lizarraga@fincamex.com.mx
A9: COTIZACION CIMBRA PARA PLANTA BAJA
A10: CANT. | B10: UND MEDIDA | C10: CONCEPTO | G10: PRECIO/UNIT | H10: PRECIO | J10: PROGRAMA | K10: % AUMENTADO | M10: REPRESENTA | O10: TOTAL
A11: =O11 -> 142.78 | B11: MT2 | C11: EQUIPO PARA MUROS (PANELES ESTANDAR | G11: =N5 -> 270 | H11: =G11*A11 -> 38550.6 | J11: 129.8 | K11: 0.1 | M11: =J11*K11 -> 12.98 | O11: =J11+M11 -> 142.78
A12: =O12 -> 43.27335 | B12: MT2 | C12: EQUIPO PARA LOSA (3 JUEGOS LOSA PUNTAL) | G12: =N5 -> 270 | H12: =A12*G12 -> 11683.804 | J12: 37.629 | K12: 0.15 | M12: =J12*K12 -> 5.64435 | O12: =J12+M12 -> 43.27335
A13: =O13 -> 22.77 | B13: MT2 | C13: EQUIPO PARA CAPS Y EQL | G13: =N5 -> 270 | H13: =A13*G13 -> 6147.9 | J13: 20.7 | K13: 0.1 | M13: =J13*K13 -> 2.07 | O13: =J13+M13 -> 22.77
A14: =O14 -> 41.8 | B14: MTL | C14: EQUIPO ANGULO DE ARRASTRE (2 plantas bajas) | G14: 25 | H14: =A14*G14 -> 1045 | J14: 38 | K14: =K11 -> 0.1 | M14: =J14*K14 -> 3.8 | O14: =J14+M14 -> 41.8
A15: INCLUYE ACCESORIOS BASICOS DE SUJECION: PASADORES, CUÑAS, CORBATAS, PUNTALES PARA VACIADO DEL MOLDE , TENSORES DE VANO, ESCALERA PARA ARMADO Y HERRAMIENTAS PARA ARMADO DE MOLDE
A16: =SUM(A11:A13) -> 208.82335 | B16: TOTAL MT2 | G16: SUBTOTAL | H16: =SUM(H11:H15) -> 57427.304
A17: =SUM(A14) -> 41.8 | B17: TOTAL ML | M17: =A16 -> 208.82335 | N17: =M17*55% -> 114.85284
N18: =M17*60% -> 125.29401
A19: =N17*-1 -> -114.85284 | B19: MT2 | C19: EQUIPO ADAPTADO DE INVENTARIO EXISTENTE MOLDE ATTALIA PLANTA BAJA | G19: =N5 -> 270 | H19: =G19*A19 -> -31010.267
A21: =A16+A19 -> 93.970507 | B21: TOTAL MT2 | C21: VALOR TOTAL EQUIPO ALUMINIO PLANTA BAJA | H21: =H16+H19 -> 26417.037 | K21: =A21*G19 -> 25372.037
A23: COTIZACION CIMBRA PARA PLANTA ALTA
A24: CANT. | B24: UND MEDIDA | C24: CONCEPTO | G24: PRECIO/UNIT | H24: PRECIO
A25: =O25 -> 163.031 | B25: MT2 | C25: EQUIPO PARA MUROS (PANELES ESTANDAR) Y CAPS | G25: =N5 -> 270 | H25: =G25*A25 -> 44018.37 | J25: 148.21 | K25: =K11 -> 0.1 | M25: =J25*K25 -> 14.821 | O25: =J25+M25 -> 163.031
A26: =O26 -> 44.62 | B26: MT2 | C26: EQUIPO PARA LOSA (3 JUEGOS LOSA PUNTAL) | G26: =N5 -> 270 | H26: =G26*A26 -> 12047.4 | J26: 38.8 | K26: =K12 -> 0.15 | M26: =J26*K26 -> 5.82 | O26: =J26+M26 -> 44.62
A27: =O27 -> 39.05 | B27: MT2 | C27: EQUIPO PARA CULATAS (PENDIENTES PARA INCLINACION 2%) | G27: =N5 -> 270 | H27: =G27*A27 -> 10543.5 | J27: 35.5 | K27: =K13 -> 0.1 | M27: =J27*K27 -> 3.55 | O27: =J27+M27 -> 39.05
A28: INCLUYE ACCESORIOS BASICOS DE SUJECION: PASADORES, CUÑAS, CORBATAS, PUNTALES PARA VACIADO DEL MOLDE , TENSORES DE VANO, ESCALERA PARA ARMADO Y HERRAMIENTAS PARA ARMADO DE MOLDE
A29: =SUM(A25:A28) -> 246.701 | B29: TOTAL MT2 | G29: SUBTOTAL | H29: =SUM(H25:H28) -> 66609.27
A31: =K33*-1 -> -124.5906 | B31: MT2 | C31: EQUIPO ADAPTADO DE INVENTARIO EXISTENTE MOLDE ATTALIA PLANTA ALTA | G31: =N5 -> 270 | H31: =G31*A31 -> -33639.462 | J31: =A25+A26 -> 207.651 | K31: =J31*60% -> 124.5906
A33: COTIZACION CIMBRA PARA PRETIL | K33: =J31*60% -> 124.5906
A34: CANT. | B34: UND MEDIDA | C34: CONCEPTO | G34: PRECIO/UNIT | H34: PRECIO
A35: =O35 -> 12.627 | B35: MT2 | C35: EQUIPO DE CIMBRA DE ALUMINIO PRETILES AZOTEA | G35: =N5 -> 270 | H35: =G35*A35 -> 3409.29 | J35: 10.98 | K35: =K26 -> 0.15 | M35: =J35*K35 -> 1.647 | O35: =J35+M35 -> 12.627
A36: =SUM(A35:A35) -> 12.627 | B36: TOTAL MT2 | G36: SUBTOTAL | H36: =SUM(H35:H35) -> 3409.29
A38: COTIZACION CIMBRA PARA ESCALERA
A39: CANT. | B39: UND MEDIDA | C39: CONCEPTO | G39: PRECIO/UNIT | H39: PRECIO
A40: =O40 -> 28.5 | B40: MT2 | C40: EQUIPO PARA CIMBRA DE UNA (1) ESCALERAS IZQ Y DERECHA PARA COLADO MONOLOTICO INTEGRADO A PAREDES | G40: 270 | H40: =G40*A40 -> 7695 | J40: 19 | K40: 0.5 | M40: =J40*K40 -> 9.5 | O40: =J40+M40 -> 28.5
A41: =SUM(A40:A40) -> 28.5 | B41: TOTAL MT2 | G41: SUBTOTAL | H41: =SUM(H40:H40) -> 7695
A43: COTIZACION CIMBRA PARA REBORDE DE FACHADA
A44: CANT. | B44: UND MEDIDA | C44: CONCEPTO | G44: PRECIO/UNIT | H44: PRECIO
A45: =O45 -> 11.0745 | B45: MT2 | C45: EQUIPO DE CIMBRA DE ALUMINIO REBORDE DE FACHADA | G45: =N5 -> 270 | H45: =G45*A45 -> 2990.115 | J45: 9.63 | K45: =K35 -> 0.15 | M45: =J45*K45 -> 1.4445 | O45: =J45+M45 -> 11.0745
A46: =SUM(A45:A45) -> 11.0745 | B46: TOTAL MT2 | G46: SUBTOTAL | H46: =SUM(H45:H45) -> 2990.115
A48: =A29+A31+A36+A41+A46 -> 174.3119 | B48: TOTAL MT2 | C48: VALOR TOTAL EQUIPO ALUMINIO PLANTA ALTA | H48: =H29+H31+H36+H41+H46 -> 47064.213
...

Sheet CTZ 232-4 CENITH-SERENA SSB (26
C1: COTIZACION FT-CTZ-01
A2: FECHA: | B2: =TODAY() -> 46320 | G2: Nº CTZ | H2: 232- 04-25 | J2: REPOTENCIACION CIMBRA DE ALUMINIO WALL TIES_ PROTOTIPO VERONA_ CIMA SERENA_ PIEZAS A REEMPLAZAR PLANTA BAJA Y PLANTA ALTA
A3: PRODUCTO COTIZADO: | C3: CIMBRA DE ALUMINIO ROBUSTFORM 5.4 | J3: MOLDE DE ALUMINIO PARA UNA 1 VIVIENDA PROTOTIPO SERENA _ PLANTA BAJA + PLANTA ALTA + ESCALERA + PRETIL + SISTEMA DE ANDAMIAJE (COMPLETO)
A4: REFERENCIA | C4: REPOTENCIACION CIMBRA DE ALUMINIO TIPO MECCANO_ PROTOTIPO CENITH A SERENA_PLANTA BAJA + PLANTA ALTA + ESCALERA + PRETIL + SISTEMA DE ANDAMIAJE (BASICO)
A5: CLIENTE: | C5: FINCAMEX | M5: PRECIO | N5: 270
A6: PAIS / CIUDAD: | C6: MEXICO / CULIACAN
A7: CONTACTO: | C7: ING. HECTOR LIZARRAGA HEREDIA | G7: TELEFONO: | H7: hector.lizarraga@fincamex.com.mx
A9: COTIZACION CIMBRA PARA PLANTA BAJA
A10: CANT. | B10: UND MEDIDA | C10: CONCEPTO | G10: PRECIO/UNIT | H10: PRECIO | J10: PROGRAMA | K10: % AUMENTADO | M10: REPRESENTA | O10: TOTAL
A11: =O11 -> 142.78 | B11: MT2 | C11: EQUIPO PARA MUROS (PANELES ESTANDAR | G11: =N5 -> 270 | H11: =G11*A11 -> 38550.6 | J11: 129.8 | K11: 0.1 | M11: =J11*K11 -> 12.98 | O11: =J11+M11 -> 142.78
A12: =O12 -> 43.27335 | B12: MT2 | C12: EQUIPO PARA LOSA (3 JUEGOS LOSA PUNTAL) | G12: =N5 -> 270 | H12: =A12*G12 -> 11683.804 | J12: 37.629 | K12: 0.15 | M12: =J12*K12 -> 5.64435 | O12: =J12+M12 -> 43.27335
A13: =O13 -> 22.77 | B13: MT2 | C13: EQUIPO PARA CAPS Y EQL | G13: =N5 -> 270 | H13: =A13*G13 -> 6147.9 | J13: 20.7 | K13: 0.1 | M13: =J13*K13 -> 2.07 | O13: =J13+M13 -> 22.77
A14: =O14 -> 41.8 | B14: MTL | C14: EQUIPO ANGULO DE ARRASTRE (2 plantas bajas) | G14: 25 | H14: =A14*G14 -> 1045 | J14: 38 | K14: =K11 -> 0.1 | M14: =J14*K14 -> 3.8 | O14: =J14+M14 -> 41.8
A15: INCLUYE ACCESORIOS BASICOS DE SUJECION: PASADORES, CUÑAS, CORBATAS, PUNTALES PARA VACIADO DEL MOLDE , TENSORES DE VANO, ESCALERA PARA ARMADO Y HERRAMIENTAS PARA ARMADO DE MOLDE
A16: =SUM(A11:A13) -> 208.82335 | B16: TOTAL MT2 | G16: SUBTOTAL | H16: =SUM(H11:H15) -> 57427.304
A17: =SUM(A14) -> 41.8 | B17: TOTAL ML | M17: 208.82 | N17: =M17*45% -> 93.969
N18: =M17*55% -> 114.851
A19: -93.9 | B19: MT2 | C19: EQUIPO ADAPTADO DE INVENTARIO EXISTENTE MECCANO MOLDE CENITH PLANTA BAJA | G19: =N5 -> 270 | H19: =G19*A19 -> -25353
A21: =A16+A19 -> 114.92335 | B21: TOTAL MT2 | C21: VALOR TOTAL EQUIPO ALUMINIO PLANTA BAJA | H21: =H16+H19 -> 32074.304 | K21: =A21*G19 -> 31029.304
A23: COTIZACION CIMBRA PARA PLANTA ALTA
A24: CANT. | B24: UND MEDIDA | C24: CONCEPTO | G24: PRECIO/UNIT | H24: PRECIO
A25: =O25 -> 163.031 | B25: MT2 | C25: EQUIPO PARA MUROS (PANELES ESTANDAR) Y CAPS | G25: =N5 -> 270 | H25: =G25*A25 -> 44018.37 | J25: 148.21 | K25: =K11 -> 0.1 | M25: =J25*K25 -> 14.821 | O25: =J25+M25 -> 163.031
A26: =O26 -> 44.62 | B26: MT2 | C26: EQUIPO PARA LOSA (3 JUEGOS LOSA PUNTAL) | G26: =N5 -> 270 | H26: =G26*A26 -> 12047.4 | J26: 38.8 | K26: =K12 -> 0.15 | M26: =J26*K26 -> 5.82 | O26: =J26+M26 -> 44.62
A27: =O27 -> 39.05 | B27: MT2 | C27: EQUIPO PARA CULATAS (PENDIENTES PARA INCLINACION 2%) | G27: =N5 -> 270 | H27: =G27*A27 -> 10543.5 | J27: 35.5 | K27: =K13 -> 0.1 | M27: =J27*K27 -> 3.55 | O27: =J27+M27 -> 39.05
A28: INCLUYE ACCESORIOS BASICOS DE SUJECION: PASADORES, CUÑAS, CORBATAS, PUNTALES PARA VACIADO DEL MOLDE , TENSORES DE VANO, ESCALERA PARA ARMADO Y HERRAMIENTAS PARA ARMADO DE MOLDE
A29: =SUM(A25:A28) -> 246.701 | B29: TOTAL MT2 | G29: SUBTOTAL | H29: =SUM(H25:H28) -> 66609.27
A31: -93.5 | B31: MT2 | C31: EQUIPO ADAPTADO DE INVENTARIO EXISTENTE MECCANO MOLDE CENITH PLANTA ALTA | G31: =N5 -> 270 | H31: =G31*A31 -> -25245 | J31: =A25+A26 -> 207.651 | K31: =J31*45% -> 93.44295
A33: COTIZACION CIMBRA PARA PRETIL | K33: =J31*55% -> 114.20805
A34: CANT. | B34: UND MEDIDA | C34: CONCEPTO | G34: PRECIO/UNIT | H34: PRECIO
A35: =O35 -> 12.627 | B35: MT2 | C35: EQUIPO DE CIMBRA DE ALUMINIO PRETILES AZOTEA | G35: =N5 -> 270 | H35: =G35*A35 -> 3409.29 | J35: 10.98 | K35: =K26 -> 0.15 | M35: =J35*K35 -> 1.647 | O35: =J35+M35 -> 12.627
A36: =SUM(A35:A35) -> 12.627 | B36: TOTAL MT2 | G36: SUBTOTAL | H36: =SUM(H35:H35) -> 3409.29
A38: COTIZACION CIMBRA PARA ESCALERA
A39: CANT. | B39: UND MEDIDA | C39: CONCEPTO | G39: PRECIO/UNIT | H39: PRECIO
A40: =O40 -> 28.5 | B40: MT2 | C40: EQUIPO PARA CIMBRA DE UNA (1) ESCALERAS IZQ Y DERECHA PARA COLADO MONOLOTICO INTEGRADO A PAREDES | G40: 270 | H40: =G40*A40 -> 7695 | J40: 19 | K40: 0.5 | M40: =J40*K40 -> 9.5 | O40: =J40+M40 -> 28.5
A41: =SUM(A40:A40) -> 28.5 | B41: TOTAL MT2 | G41: SUBTOTAL | H41: =SUM(H40:H40) -> 7695
A43: COTIZACION CIMBRA PARA REBORDE DE FACHADA
A44: CANT. | B44: UND MEDIDA | C44: CONCEPTO | G44: PRECIO/UNIT | H44: PRECIO
A45: =O45 -> 11.0745 | B45: MT2 | C45: EQUIPO DE CIMBRA DE ALUMINIO REBORDE DE FACHADA | G45: =N5 -> 270 | H45: =G45*A45 -> 2990.115 | J45: 9.63 | K45: =K35 -> 0.15 | M45: =J45*K45 -> 1.4445 | O45: =J45+M45 -> 11.0745
A46: =SUM(A45:A45) -> 11.0745 | B46: TOTAL MT2 | G46: SUBTOTAL | H46: =SUM(H45:H45) -> 2990.115
A48: =A29+A31+A36+A41+A46 -> 205.4025 | B48: TOTAL MT2 | C48: VALOR TOTAL EQUIPO ALUMINIO PLANTA ALTA | H48: =H29+H31+H36+H41+H46 -> 55458.675
...

Sheet CTZ 232-6 ATTALI-SERENA SSB(26)
C1: COTIZACION FT-CTZ-01
A2: FECHA: | B2: =TODAY() -> 46320 | G2: Nº CTZ | H2: 232- 06-26 | J2: REPOTENCIACION CIMBRA DE ALUMINIO WALL TIES_ PROTOTIPO VERONA_ CIMA SERENA_ PIEZAS A REEMPLAZAR PLANTA BAJA Y PLANTA ALTA
A3: PRODUCTO COTIZADO: | C3: CIMBRA DE ALUMINIO ROBUSTFORM 5.4 | J3: MOLDE DE ALUMINIO PARA UNA 1 VIVIENDA PROTOTIPO SERENA _ PLANTA BAJA + PLANTA ALTA + ESCALERA + PRETIL + SISTEMA DE ANDAMIAJE (COMPLETO)
A4: REFERENCIA | C4: REPOTENCIACION CIMBRA DE ALUMINIO TIPO CMR_ PROTOTIPO ATTALIA A SERENA_PLANTA BAJA + PLANTA ALTA + ESCALERA + PRETIL + SISTEMA DE ANDAMIAJE (BASICO)
A5: CLIENTE: | C5: FINCAMEX | M5: PRECIO | N5: 270
A6: PAIS / CIUDAD: | C6: MEXICO / CULIACAN
A7: CONTACTO: | C7: ING. HECTOR LIZARRAGA HEREDIA | G7: TELEFONO: | H7: hector.lizarraga@fincamex.com.mx
A9: COTIZACION CIMBRA PARA PLANTA BAJA
A10: CANT. | B10: UND MEDIDA | C10: CONCEPTO | G10: PRECIO/UNIT | H10: PRECIO | J10: PROGRAMA | K10: % AUMENTADO | M10: REPRESENTA | O10: TOTAL
A11: =O11 -> 142.78 | B11: MT2 | C11: EQUIPO PARA MUROS (PANELES ESTANDAR | G11: =N5 -> 270 | H11: =G11*A11 -> 38550.6 | J11: 129.8 | K11: 0.1 | M11: =J11*K11 -> 12.98 | O11: =J11+M11 -> 142.78
A12: =O12 -> 43.27335 | B12: MT2 | C12: EQUIPO PARA LOSA (3 JUEGOS LOSA PUNTAL) | G12: =N5 -> 270 | H12: =A12*G12 -> 11683.804 | J12: 37.629 | K12: 0.15 | M12: =J12*K12 -> 5.64435 | O12: =J12+M12 -> 43.27335
A13: =O13 -> 22.77 | B13: MT2 | C13: EQUIPO PARA CAPS Y EQL | G13: =N5 -> 270 | H13: =A13*G13 -> 6147.9 | J13: 20.7 | K13: 0.1 | M13: =J13*K13 -> 2.07 | O13: =J13+M13 -> 22.77
A14: =O14 -> 41.8 | B14: MTL | C14: EQUIPO ANGULO DE ARRASTRE (2 plantas bajas) | G14: 25 | H14: =A14*G14 -> 1045 | J14: 38 | K14: =K11 -> 0.1 | M14: =J14*K14 -> 3.8 | O14: =J14+M14 -> 41.8
A15: INCLUYE ACCESORIOS BASICOS DE SUJECION: PASADORES, CUÑAS, CORBATAS, PUNTALES PARA VACIADO DEL MOLDE , TENSORES DE VANO, ESCALERA PARA ARMADO Y HERRAMIENTAS PARA ARMADO DE MOLDE
A16: =SUM(A11:A13) -> 208.82335 | B16: TOTAL MT2 | G16: SUBTOTAL | H16: =SUM(H11:H15) -> 57427.304
A17: =SUM(A14) -> 41.8 | B17: TOTAL ML | M17: 208.82 | N17: =M17*45% -> 93.969
N18: =M17*55% -> 114.851
A19: ='CTZ 232-5 athali-SERENA SSC(26)'!A19 -> -114.85284 | B19: MT2 | C19: EQUIPO ADAPTADO DE INVENTARIO EXISTENTE MOLDE ATTALIA PLANTA BAJA | G19: =N5 -> 270 | H19: =G19*A19 -> -31010.267
A21: =A16+A19 -> 93.970507 | B21: TOTAL MT2 | C21: VALOR TOTAL EQUIPO ALUMINIO PLANTA BAJA | H21: =H16+H19 -> 26417.037 | K21: =A21*G19 -> 25372.037
A23: COTIZACION CIMBRA PARA PLANTA ALTA
A24: CANT. | B24: UND MEDIDA | C24: CONCEPTO | G24: PRECIO/UNIT | H24: PRECIO
A25: =O25 -> 163.031 | B25: MT2 | C25: EQUIPO PARA MUROS (PANELES ESTANDAR) Y CAPS | G25: =N5 -> 270 | H25: =G25*A25 -> 44018.37 | J25: 148.21 | K25: =K11 -> 0.1 | M25: =J25*K25 -> 14.821 | O25: =J25+M25 -> 163.031
A26: =O26 -> 44.62 | B26: MT2 | C26: EQUIPO PARA LOSA (3 JUEGOS LOSA PUNTAL) | G26: =N5 -> 270 | H26: =G26*A26 -> 12047.4 | J26: 38.8 | K26: =K12 -> 0.15 | M26: =J26*K26 -> 5.82 | O26: =J26+M26 -> 44.62
A27: =O27 -> 39.05 | B27: MT2 | C27: EQUIPO PARA CULATAS (PENDIENTES PARA INCLINACION 2%) | G27: =N5 -> 270 | H27: =G27*A27 -> 10543.5 | J27: 35.5 | K27: =K13 -> 0.1 | M27: =J27*K27 -> 3.55 | O27: =J27+M27 -> 39.05
A28: INCLUYE ACCESORIOS BASICOS DE SUJECION: PASADORES, CUÑAS, CORBATAS, PUNTALES PARA VACIADO DEL MOLDE , TENSORES DE VANO, ESCALERA PARA ARMADO Y HERRAMIENTAS PARA ARMADO DE MOLDE
A29: =SUM(A25:A28) -> 246.701 | B29: TOTAL MT2 | G29: SUBTOTAL | H29: =SUM(H25:H28) -> 66609.27
A31: ='CTZ 232-5 athali-SERENA SSC(26)'!A31 -> -124.5906 | B31: MT2 | C31: EQUIPO ADAPTADO DE INVENTARIO EXISTENTE MOLDE ATTALIA PLANTA ALTA | G31: =N5 -> 270 | H31: =G31*A31 -> -33639.462 | J31: =A25+A26 -> 207.651 | K31: =J31*45% -> 93.44295
A33: COTIZACION CIMBRA PARA PRETIL | K33: =J31*55% -> 114.20805
A34: CANT. | B34: UND MEDIDA | C34: CONCEPTO | G34: PRECIO/UNIT | H34: PRECIO
A35: =O35 -> 12.627 | B35: MT2 | C35: EQUIPO DE CIMBRA DE ALUMINIO PRETILES AZOTEA | G35: =N5 -> 270 | H35: =G35*A35 -> 3409.29 | J35: 10.98 | K35: =K26 -> 0.15 | M35: =J35*K35 -> 1.647 | O35: =J35+M35 -> 12.627
A36: =SUM(A35:A35) -> 12.627 | B36: TOTAL MT2 | G36: SUBTOTAL | H36: =SUM(H35:H35) -> 3409.29
A38: COTIZACION CIMBRA PARA ESCALERA
A39: CANT. | B39: UND MEDIDA | C39: CONCEPTO | G39: PRECIO/UNIT | H39: PRECIO
A40: =O40 -> 28.5 | B40: MT2 | C40: EQUIPO PARA CIMBRA DE UNA (1) ESCALERAS IZQ Y DERECHA PARA COLADO MONOLOTICO INTEGRADO A PAREDES | G40: 270 | H40: =G40*A40 -> 7695 | J40: 19 | K40: 0.5 | M40: =J40*K40 -> 9.5 | O40: =J40+M40 -> 28.5
A41: =SUM(A40:A40) -> 28.5 | B41: TOTAL MT2 | G41: SUBTOTAL | H41: =SUM(H40:H40) -> 7695
A43: COTIZACION CIMBRA PARA REBORDE DE FACHADA
A44: CANT. | B44: UND MEDIDA | C44: CONCEPTO | G44: PRECIO/UNIT | H44: PRECIO
A45: =O45 -> 11.0745 | B45: MT2 | C45: EQUIPO DE CIMBRA DE ALUMINIO REBORDE DE FACHADA | G45: =N5 -> 270 | H45: =G45*A45 -> 2990.115 | J45: 9.63 | K45: =K35 -> 0.15 | M45: =J45*K45 -> 1.4445 | O45: =J45+M45 -> 11.0745
A46: =SUM(A45:A45) -> 11.0745 | B46: TOTAL MT2 | G46: SUBTOTAL | H46: =SUM(H45:H45) -> 2990.115
A48: =A29+A31+A36+A41+A46 -> 174.3119 | B48: TOTAL MT2 | C48: VALOR TOTAL EQUIPO ALUMINIO PLANTA ALTA | H48: =H29+H31+H36+H41+H46 -> 47064.213
...
