Workbook

Sheet ÁREAS E IMÁGENES
F1: MEMORIA DE ÁREAS
N2: FECHA | O2: =+'1. EQ. BASE'!$H$7 -> 0
N3: COTIZACIÓN | O3: XXXXXX
N4: PROYECTO | O4: =+'1. EQ. BASE'!$C$7 -> 0
N5: CLIENTE | O5: =+'1. EQ. BASE'!$C$6 -> 0
N6: PROYECTISTA | O6: =+'1. EQ. BASE'!$H$6 -> 0
V7: CÓDIGO
C9: EQUIPO INDEPENDIENTE | N9: SOLO AREA COMERCIAL
C10: =+'1. EQ. BASE'!$C$8 -> 1. EQ. BASE | D10: =+'2. EQ. ADIC. "A"'!$C$8 -> 2. EQ. ADIC. "A" | E10: =+'3. EQ. ADIC. "B"'!$C$8 -> 3. EQ. ADIC. "B" | F10: =+'4. EQ. ADIC. "C"'!$C$8 -> 4. EQ. ADIC. "C" | G10: =+'5. EQ. ADIC. "D"'!$C$8 -> 5. EQ. ADIC. "D" | H10: =+'6. EQ. ADIC. "E"'!$C$8 -> 6. EQ. ADIC. "E" | I10: =+'7. EQ. ADIC. "F"'!$C$8 -> 7. EQ. ADIC. "F" | J10: =+'8. EQ. ADIC. "G"'!C8 -> 8. EQ. ADIC. "G" | K10: =+'9. EQ. ADIC. "H"'!$C$8 -> 9. EQ. ADIC. "H" | L10: =+'10. EQ. ADIC. "I"'!$C$8 -> 10. EQ. ADIC. "I" | M10: TOTAL | N10: % | O10: AREA +%
B11: MUROS | C11: =+'1. EQ. BASE'!$O$9 -> 0 | D11: =+'2. EQ. ADIC. "A"'!$O$9 -> 0 | E11: =+'3. EQ. ADIC. "B"'!$O$9 -> 0 | F11: =+'4. EQ. ADIC. "C"'!$O$9 -> 0 | G11: =+'5. EQ. ADIC. "D"'!$O$9 -> 0 | H11: =+'6. EQ. ADIC. "E"'!$O$9 -> 0 | I11: =+'7. EQ. ADIC. "F"'!$O$9 -> 0 | J11: =+'8. EQ. ADIC. "G"'!$O$9 -> 0 | K11: =+'9. EQ. ADIC. "H"'!$O$9 -> 0 | L11: =+'10. EQ. ADIC. "I"'!$O$9 -> 0 | M11: =SUM(C11:L11) -> 0 | O11: =+(M11*N11)+M11 -> 0
B12: LOSA | C12: =+'1. EQ. BASE'!$Q$9 -> 0 | D12: =+'2. EQ. ADIC. "A"'!$Q$9 -> 0 | E12: =+'3. EQ. ADIC. "B"'!$Q$9 -> 0 | F12: =+'4. EQ. ADIC. "C"'!$Q$9 -> 0 | G12: =+'5. EQ. ADIC. "D"'!$Q$9 -> 0 | H12: =+'6. EQ. ADIC. "E"'!$Q$9 -> 0 | I12: =+'7. EQ. ADIC. "F"'!$Q$9 -> 0 | J12: =+'8. EQ. ADIC. "G"'!$Q$9 -> 0 | K12: =+'9. EQ. ADIC. "H"'!$Q$9 -> 0 | L12: =+'10. EQ. ADIC. "I"'!$Q$9 -> 0 | M12: =SUM(C12:L12) -> 0 | O12: =+(M12*N12)+M12 -> 0
B13: UNION MURO LOSA | C13: =+'1. EQ. BASE'!$S$3 -> 0 | D13: =+'2. EQ. ADIC. "A"'!$S$3 -> 0 | E13: =+'3. EQ. ADIC. "B"'!$S$3 -> 0 | F13: =+'4. EQ. ADIC. "C"'!$S$3 -> 0 | G13: =+'5. EQ. ADIC. "D"'!$S$3 -> 0 | H13: =+'6. EQ. ADIC. "E"'!$S$3 -> 0 | I13: =+'7. EQ. ADIC. "F"'!$S$3 -> 0 | J13: =+'8. EQ. ADIC. "G"'!$S$3 -> 0 | K13: =+'9. EQ. ADIC. "H"'!$S$3 -> 0 | L13: =+'10. EQ. ADIC. "I"'!$S$3 -> 0 | M13: =SUM(C13:L13) -> 0 | O13: =+(M13*N13)+M13 -> 0
B14: CULATAS | C14: =+'1. EQ. BASE'!$U$9 -> 0 | D14: =+'2. EQ. ADIC. "A"'!$U$9 -> 0 | E14: =+'3. EQ. ADIC. "B"'!$U$9 -> 0 | F14: =+'4. EQ. ADIC. "C"'!$U$9 -> 0 | G14: =+'5. EQ. ADIC. "D"'!$U$9 -> 0 | H14: =+'6. EQ. ADIC. "E"'!$U$9 -> 0 | I14: =+'7. EQ. ADIC. "F"'!$U$9 -> 0 | J14: =+'8. EQ. ADIC. "G"'!$U$9 -> 0 | K14: =+'9. EQ. ADIC. "H"'!$U$9 -> 0 | L14: =+'10. EQ. ADIC. "I"'!$U$9 -> 0 | M14: =SUM(C14:L14) -> 0 | O14: =+(M14*N14)+M14 -> 0
C15: =SUM(C11:C14) -> 0 | D15: =SUM(D11:D14) -> 0 | E15: =SUM(E11:E14) -> 0 | F15: =SUM(F11:F14) -> 0 | G15: =SUM(G11:G14) -> 0 | H15: =SUM(H11:H14) -> 0 | I15: =SUM(I11:I14) -> 0 | J15: =SUM(J11:J14) -> 0 | ... L15: =SUM(L11:L14) -> 0 | M15: =SUM(C15:L15) -> 0 | O15: =SUM(O11:O14) -> 0
C31: IMAGEN MUROS | G31: IMAGEN LOSA | K31: IMAGEN CULATAS | O31: IMAGEN MODELO COMPLETO
C34: EQUIPO ADICIONAL | O34: SOLO AREA COMERCIAL
C35: PRETIL | E35: ESCALERA PL. BAJA | F35: ESCALERA 1ER NIVEL | G35: ESCALERA 2DO NIVEL | H35: ESCALERA ULTIMO NIVEL | I35: PUNTO FIJO PL. BAJA | J35: PUNTO FIJO 1ER NIVEL | K35: PUNTO FIJO 2DO NIVEL | L35: PUNTO FIJO ULTIMO NIVEL | M35: TINACO | N35: TOTAL | O35: % | P35: AREA +%
B36: MUROS | C36: =+'1. EQ. BASE'!$S$9 -> 0 | N36: =SUM(C36:M36) -> 0 | P36: =+(N36*O36)+N36 -> 0
B37: LOSA | N37: =SUM(C37:M37) -> 0 | P37: =+(N37*O37)+N37 -> 0
B38: UNION MURO LOSA | N38: =SUM(C38:M38) -> 0 | P38: =+(N38*O38)+N38 -> 0
B39: CULATAS | N39: =SUM(C39:M39) -> 0 | P39: =+(N39*O39)+N39 -> 0
B40: ESCALERA | N40: =SUM(C40:M40) -> 0 | P40: =+(N40*O40)+N40 -> 0
C41: =SUM(C36:C40) -> 0 | D41: =SUM(D36:D40) -> 0 | E41: =SUM(E36:E40) -> 0 | F41: =SUM(F36:F40) -> 0 | G41: =SUM(G36:G40) -> 0 | H41: =SUM(H36:H40) -> 0 | I41: =SUM(I36:I40) -> 0 | J41: =SUM(J36:J40) -> 0 | ... M41: =SUM(M36:M40) -> 0 | N41: =SUM(C41:M41) -> 0 | P41: =SUM(P36:P40) -> 0
B57: IMAGEN PRETIL | F57: IMAGEN ESCALERA | K57: IMAGEN PUNTO FIJO | P57: IMAGEN TINACO
B60: PERIMETRO ANDAMIAJE | K60: PERIMETRO ÁNGULO DE ARRASTRE
C62: DESCRIPCIÓN DEL ALCANCE | D62: PERÍMETRO COMPLETO | L62: DESCRIPCIÓN DEL ALCANCE | M62: PERÍMETRO COMPLETO
G72: PERIMETRO PARA ANDAMIAJE | O72: PERIMETRO PARA ANGULO DE ARRASTE

Sheet 1. EQ. BASE
D1: LISTA DE EMPAQUE PARA ÁREAS | H1: No. | N1: EQUIPO MUROS | P1: EQUIPO LOSA | R1: EQUIPO UNION MURO LOSA | T1: EQUIPO CULATAS
K2: AREA TOTAL | N2: ANGULOS PARA MUROS | O2: =+$B20 -> 0 | P2: ANGULOS PARA LOSA | Q2: =+$B31 -> 0 | R2: EQL | S2: =+$B283 -> 0 | T2: ESQUINEROS EQMT | U2: =+$B94 -> 0
K3: =+$O$9+$Q$9+$S$3+$U$9+$S$9 -> 0 | N3: ESQUINEROS DE MURO | O3: =+$B52 -> 0 | P3: ESQUINEROS DE MURO C/TAPA | Q3: =+$B73 -> 0 | R3: SUBTOTAL | S3: =SUM($S$2) -> 0 | T3: EQL CON PENDIENTE | U3: =+$B304 -> 0
N4: FORMALETAS DE MURO | O4: =+$B115 -> 0 | P4: FORMALETA DE LOSA, FLP (SON 3) | Q4: =+$B157 -> 0 | R4: PRETIL | T4: CULATAS | U4: =+$B325 -> 0
N5: TAPAS, TAPA PUNTAL (SON 3) | O5: =+$B136 -> 0 | P5: CAPS / BORDE DE LOSA | Q5: =+$B178 -> 0 | R5: CAPS PRETIL | S5: =+$B199 -> 0 | T5: CULATAS CUMBRERA | U5: =+$B346 -> 0
A6: CLIENTE: | F6: ELABORADO POR: | R6: CAPS PRETIL C/PENDIENTE | S6: =+$B220 -> 0 | T6: CULATÓN | U6: =+$B367 -> 0
A7: PROYECTO: | F7: FECHA: | R7: EQMP | S7: =+$B241 -> 0 | T7: CULATÓN CUMBRERA | U7: =+$B388 -> 0
A8: REFERENCIA: | C8: 1. EQ. BASE | R8: EQMP C/PENDIENTE | S8: =+$B242 -> 0
N9: SUBTOTAL | O9: =SUM($O$2:$O$5) -> 0 | P9: SUBTOTAL | Q9: =SUM($Q$2:$Q$5) -> 0 | R9: SUBTOTAL | S9: =SUM($S$5:$S$8) -> 0 | T9: SUBTOTAL | U9: =SUM($U$2:$U$7) -> 0
A11: ÁNGULOS PARA MUROS (AG) | I11: MUROS
A12: ITEM | B12: CAN. | C12: DESCRIPCION | D12: ANC1 | E12: ALT1 | F12: ALT2 | G12: ANC2 | H12: OBSERVACIONES
A13: 1 | K13: =((D13+G13)*E13)/10000 -> 0 | L13: =K13*B13 -> 0
A14: =+A13+1 -> 2 | K14: =((D14+G14)*E14)/10000 -> 0 | L14: =K14*B14 -> 0
A15: =+A14+1 -> 3 | K15: =((D15+G15)*E15)/10000 -> 0 | L15: =K15*B15 -> 0
A16: =+A15+1 -> 4 | K16: =((D16+G16)*E16)/10000 -> 0 | L16: =K16*B16 -> 0
A17: =+A16+1 -> 5 | K17: =((D17+G17)*E17)/10000 -> 0 | L17: =K17*B17 -> 0
B19: =SUM(B13:B18) -> 0 | C19: TOTAL ÁNGULOS PARA MUROS | L19: =SUM(L13:L18) -> 0
B20: =+$L19 -> 0 | C20: TOTAL M²
A22: ÁNGULOS PARA LOSA (AG) | I22: LOSA
A23: ITEM | B23: CAN. | C23: DESCRIPCION | D23: ANC1 | E23: ALT1 | F23: ALT2 | G23: ANC2 | H23: OBSERVACIONES
A24: 1 | K24: =((D24+G24)*E24)/10000 -> 0 | L24: =K24*B24 -> 0
A25: =+A24+1 -> 2 | K25: =((D25+G25)*E25)/10000 -> 0 | L25: =K25*B25 -> 0
A26: =+A25+1 -> 3 | K26: =((D26+G26)*E26)/10000 -> 0 | L26: =K26*B26 -> 0
A27: =+A26+1 -> 4 | K27: =((D27+G27)*E27)/10000 -> 0 | L27: =K27*B27 -> 0
A28: =+A27+1 -> 5 | K28: =((D28+G28)*E28)/10000 -> 0 | L28: =K28*B28 -> 0
B30: =SUM(B24:B29) -> 0 | C30: TOTAL ÁNGULOS PARA LOSA | L30: =SUM(L24:L29) -> 0
B31: =+$L30 -> 0 | C31: TOTAL M²
A33: ESQUINEROS DE MURO (EQM) | I33: MUROS
A34: ITEM | B34: CAN. | C34: DESCRIPCION | D34: ANC1 | E34: ALT1 | F34: ALT2 | G34: ANC2 | H34: OBSERVACIONES
A35: 1 | K35: =((D35+G35)*E35)/10000 -> 0 | L35: =K35*B35 -> 0
A36: =+A35+1 -> 2 | K36: =((D36+G36)*E36)/10000 -> 0 | L36: =K36*B36 -> 0
A37: =+A36+1 -> 3 | K37: =((D37+G37)*E37)/10000 -> 0 | L37: =K37*B37 -> 0
A38: =+A37+1 -> 4 | K38: =((D38+G38)*E38)/10000 -> 0 | L38: =K38*B38 -> 0
A39: =+A38+1 -> 5 | K39: =((D39+G39)*E39)/10000 -> 0 | L39: =K39*B39 -> 0
A40: =+A39+1 -> 6 | K40: =((D40+G40)*E40)/10000 -> 0 | L40: =K40*B40 -> 0
A41: =+A40+1 -> 7 | K41: =((D41+G41)*E41)/10000 -> 0 | L41: =K41*B41 -> 0
A42: =+A41+1 -> 8 | K42: =((D42+G42)*E42)/10000 -> 0 | L42: =K42*B42 -> 0
A43: =+A42+1 -> 9 | K43: =((D43+G43)*E43)/10000 -> 0 | L43: =K43*B43 -> 0
A44: =+A43+1 -> 10 | K44: =((D44+G44)*E44)/10000 -> 0 | L44: =K44*B44 -> 0
A45: =+A44+1 -> 11 | K45: =((D45+G45)*E45)/10000 -> 0 | L45: =K45*B45 -> 0
...

Sheet 2. EQ. ADIC. "A"
D1: LISTA DE EMPAQUE PARA ÁREAS | H1: No. | N1: EQUIPO MUROS | P1: EQUIPO LOSA | R1: EQUIPO UNION MURO LOSA | T1: EQUIPO CULATAS
K2: AREA TOTAL | N2: ANGULOS PARA MUROS | O2: =+$B20 -> 0 | P2: ANGULOS PARA LOSA | Q2: =+$B31 -> 0 | R2: EQL | S2: =+$B283 -> 0 | T2: ESQUINEROS EQMT | U2: =+$B94 -> 0
K3: =+$O$9+$Q$9+$S$3+$U$9+$S$9 -> 0 | N3: ESQUINEROS DE MURO | O3: =+$B52 -> 0 | P3: ESQUINEROS DE MURO C/TAPA | Q3: =+$B73 -> 0 | R3: SUBTOTAL | S3: =SUM($S$2) -> 0 | T3: EQL CON PENDIENTE | U3: =+$B304 -> 0
N4: FORMALETAS DE MURO | O4: =+$B115 -> 0 | P4: FORMALETA DE LOSA, FLP (SON 3) | Q4: =+$B157 -> 0 | R4: PRETIL | T4: CULATAS | U4: =+$B325 -> 0
N5: TAPAS, TAPA PUNTAL (SON 3) | O5: =+$B136 -> 0 | P5: CAPS / BORDE DE LOSA | Q5: =+$B178 -> 0 | R5: CAPS PRETIL | S5: =+$B199 -> 0 | T5: CULATAS CUMBRERA | U5: =+$B346 -> 0
A6: CLIENTE: | F6: ELABORADO POR: | R6: CAPS PRETIL C/PENDIENTE | S6: =+$B220 -> 0 | T6: CULATÓN | U6: =+$B367 -> 0
A7: PROYECTO: | F7: FECHA: | R7: EQMP | S7: =+$B241 -> 0 | T7: CULATÓN CUMBRERA | U7: =+$B388 -> 0
A8: REFERENCIA: | C8: 2. EQ. ADIC. "A" | R8: EQMP C/PENDIENTE | S8: =+$B242 -> 0
N9: SUBTOTAL | O9: =SUM($O$2:$O$5) -> 0 | P9: SUBTOTAL | Q9: =SUM($Q$2:$Q$5) -> 0 | R9: SUBTOTAL | S9: =SUM($S$5:$S$8) -> 0 | T9: SUBTOTAL | U9: =SUM($U$2:$U$7) -> 0
A11: ÁNGULOS PARA MUROS (AG) | I11: MUROS
A12: ITEM | B12: CAN. | C12: DESCRIPCION | D12: ANC1 | E12: ALT1 | F12: ALT2 | G12: ANC2 | H12: OBSERVACIONES
A13: 1 | K13: =((D13+G13)*E13)/10000 -> 0 | L13: =K13*B13 -> 0
A14: =+A13+1 -> 2 | K14: =((D14+G14)*E14)/10000 -> 0 | L14: =K14*B14 -> 0
A15: =+A14+1 -> 3 | K15: =((D15+G15)*E15)/10000 -> 0 | L15: =K15*B15 -> 0
A16: =+A15+1 -> 4 | K16: =((D16+G16)*E16)/10000 -> 0 | L16: =K16*B16 -> 0
A17: =+A16+1 -> 5 | K17: =((D17+G17)*E17)/10000 -> 0 | L17: =K17*B17 -> 0
B19: =SUM(B13:B18) -> 0 | C19: TOTAL ÁNGULOS PARA MUROS | L19: =SUM(L13:L18) -> 0
B20: =+$L19 -> 0 | C20: TOTAL M²
A22: ÁNGULOS PARA LOSA (AG) | I22: LOSA
A23: ITEM | B23: CAN. | C23: DESCRIPCION | D23: ANC1 | E23: ALT1 | F23: ALT2 | G23: ANC2 | H23: OBSERVACIONES
A24: 1 | K24: =((D24+G24)*E24)/10000 -> 0 | L24: =K24*B24 -> 0
A25: =+A24+1 -> 2 | K25: =((D25+G25)*E25)/10000 -> 0 | L25: =K25*B25 -> 0
A26: =+A25+1 -> 3 | K26: =((D26+G26)*E26)/10000 -> 0 | L26: =K26*B26 -> 0
A27: =+A26+1 -> 4 | K27: =((D27+G27)*E27)/10000 -> 0 | L27: =K27*B27 -> 0
A28: =+A27+1 -> 5 | K28: =((D28+G28)*E28)/10000 -> 0 | L28: =K28*B28 -> 0
B30: =SUM(B24:B29) -> 0 | C30: TOTAL ÁNGULOS PARA LOSA | L30: =SUM(L24:L29) -> 0
B31: =+$L30 -> 0 | C31: TOTAL M²
A33: ESQUINEROS DE MURO (EQM) | I33: MUROS
A34: ITEM | B34: CAN. | C34: DESCRIPCION | D34: ANC1 | E34: ALT1 | F34: ALT2 | G34: ANC2 | H34: OBSERVACIONES
A35: 1 | K35: =((D35+G35)*E35)/10000 -> 0 | L35: =K35*B35 -> 0
A36: =+A35+1 -> 2 | K36: =((D36+G36)*E36)/10000 -> 0 | L36: =K36*B36 -> 0
A37: =+A36+1 -> 3 | K37: =((D37+G37)*E37)/10000 -> 0 | L37: =K37*B37 -> 0
A38: =+A37+1 -> 4 | K38: =((D38+G38)*E38)/10000 -> 0 | L38: =K38*B38 -> 0
A39: =+A38+1 -> 5 | K39: =((D39+G39)*E39)/10000 -> 0 | L39: =K39*B39 -> 0
A40: =+A39+1 -> 6 | K40: =((D40+G40)*E40)/10000 -> 0 | L40: =K40*B40 -> 0
A41: =+A40+1 -> 7 | K41: =((D41+G41)*E41)/10000 -> 0 | L41: =K41*B41 -> 0
A42: =+A41+1 -> 8 | K42: =((D42+G42)*E42)/10000 -> 0 | L42: =K42*B42 -> 0
A43: =+A42+1 -> 9 | K43: =((D43+G43)*E43)/10000 -> 0 | L43: =K43*B43 -> 0
A44: =+A43+1 -> 10 | K44: =((D44+G44)*E44)/10000 -> 0 | L44: =K44*B44 -> 0
A45: =+A44+1 -> 11 | K45: =((D45+G45)*E45)/10000 -> 0 | L45: =K45*B45 -> 0
...

Sheet 3. EQ. ADIC. "B"
D1: LISTA DE EMPAQUE PARA ÁREAS | H1: No. | N1: EQUIPO MUROS | P1: EQUIPO LOSA | R1: EQUIPO UNION MURO LOSA | T1: EQUIPO CULATAS
K2: AREA TOTAL | N2: ANGULOS PARA MUROS | O2: =+$B20 -> 0 | P2: ANGULOS PARA LOSA | Q2: =+$B31 -> 0 | R2: EQL | S2: =+$B283 -> 0 | T2: ESQUINEROS EQMT | U2: =+$B94 -> 0
K3: =+$O$9+$Q$9+$S$3+$U$9+$S$9 -> 0 | N3: ESQUINEROS DE MURO | O3: =+$B52 -> 0 | P3: ESQUINEROS DE MURO C/TAPA | Q3: =+$B73 -> 0 | R3: SUBTOTAL | S3: =SUM($S$2) -> 0 | T3: EQL CON PENDIENTE | U3: =+$B304 -> 0
N4: FORMALETAS DE MURO | O4: =+$B115 -> 0 | P4: FORMALETA DE LOSA, FLP (SON 3) | Q4: =+$B157 -> 0 | R4: PRETIL | T4: CULATAS | U4: =+$B325 -> 0
N5: TAPAS, TAPA PUNTAL (SON 3) | O5: =+$B136 -> 0 | P5: CAPS / BORDE DE LOSA | Q5: =+$B178 -> 0 | R5: CAPS PRETIL | S5: =+$B199 -> 0 | T5: CULATAS CUMBRERA | U5: =+$B346 -> 0
A6: CLIENTE: | F6: ELABORADO POR: | R6: CAPS PRETIL C/PENDIENTE | S6: =+$B220 -> 0 | T6: CULATÓN | U6: =+$B367 -> 0
A7: PROYECTO: | F7: FECHA: | R7: EQMP | S7: =+$B241 -> 0 | T7: CULATÓN CUMBRERA | U7: =+$B388 -> 0
A8: REFERENCIA: | C8: 3. EQ. ADIC. "B" | R8: EQMP C/PENDIENTE | S8: =+$B242 -> 0
N9: SUBTOTAL | O9: =SUM($O$2:$O$5) -> 0 | P9: SUBTOTAL | Q9: =SUM($Q$2:$Q$5) -> 0 | R9: SUBTOTAL | S9: =SUM($S$5:$S$8) -> 0 | T9: SUBTOTAL | U9: =SUM($U$2:$U$7) -> 0
A11: ÁNGULOS PARA MUROS (AG) | I11: MUROS
A12: ITEM | B12: CAN. | C12: DESCRIPCION | D12: ANC1 | E12: ALT1 | F12: ALT2 | G12: ANC2 | H12: OBSERVACIONES
A13: 1 | K13: =((D13+G13)*E13)/10000 -> 0 | L13: =K13*B13 -> 0
A14: =+A13+1 -> 2 | K14: =((D14+G14)*E14)/10000 -> 0 | L14: =K14*B14 -> 0
A15: =+A14+1 -> 3 | K15: =((D15+G15)*E15)/10000 -> 0 | L15: =K15*B15 -> 0
A16: =+A15+1 -> 4 | K16: =((D16+G16)*E16)/10000 -> 0 | L16: =K16*B16 -> 0
A17: =+A16+1 -> 5 | K17: =((D17+G17)*E17)/10000 -> 0 | L17: =K17*B17 -> 0
B19: =SUM(B13:B18) -> 0 | C19: TOTAL ÁNGULOS PARA MUROS | L19: =SUM(L13:L18) -> 0
B20: =+$L19 -> 0 | C20: TOTAL M²
A22: ÁNGULOS PARA LOSA (AG) | I22: LOSA
A23: ITEM | B23: CAN. | C23: DESCRIPCION | D23: ANC1 | E23: ALT1 | F23: ALT2 | G23: ANC2 | H23: OBSERVACIONES
A24: 1 | K24: =((D24+G24)*E24)/10000 -> 0 | L24: =K24*B24 -> 0
A25: =+A24+1 -> 2 | K25: =((D25+G25)*E25)/10000 -> 0 | L25: =K25*B25 -> 0
A26: =+A25+1 -> 3 | K26: =((D26+G26)*E26)/10000 -> 0 | L26: =K26*B26 -> 0
A27: =+A26+1 -> 4 | K27: =((D27+G27)*E27)/10000 -> 0 | L27: =K27*B27 -> 0
A28: =+A27+1 -> 5 | K28: =((D28+G28)*E28)/10000 -> 0 | L28: =K28*B28 -> 0
B30: =SUM(B24:B29) -> 0 | C30: TOTAL ÁNGULOS PARA LOSA | L30: =SUM(L24:L29) -> 0
B31: =+$L30 -> 0 | C31: TOTAL M²
A33: ESQUINEROS DE MURO (EQM) | I33: MUROS
A34: ITEM | B34: CAN. | C34: DESCRIPCION | D34: ANC1 | E34: ALT1 | F34: ALT2 | G34: ANC2 | H34: OBSERVACIONES
A35: 1 | K35: =((D35+G35)*E35)/10000 -> 0 | L35: =K35*B35 -> 0
A36: =+A35+1 -> 2 | K36: =((D36+G36)*E36)/10000 -> 0 | L36: =K36*B36 -> 0
A37: =+A36+1 -> 3 | K37: =((D37+G37)*E37)/10000 -> 0 | L37: =K37*B37 -> 0
A38: =+A37+1 -> 4 | K38: =((D38+G38)*E38)/10000 -> 0 | L38: =K38*B38 -> 0
A39: =+A38+1 -> 5 | K39: =((D39+G39)*E39)/10000 -> 0 | L39: =K39*B39 -> 0
A40: =+A39+1 -> 6 | K40: =((D40+G40)*E40)/10000 -> 0 | L40: =K40*B40 -> 0
A41: =+A40+1 -> 7 | K41: =((D41+G41)*E41)/10000 -> 0 | L41: =K41*B41 -> 0
A42: =+A41+1 -> 8 | K42: =((D42+G42)*E42)/10000 -> 0 | L42: =K42*B42 -> 0
A43: =+A42+1 -> 9 | K43: =((D43+G43)*E43)/10000 -> 0 | L43: =K43*B43 -> 0
A44: =+A43+1 -> 10 | K44: =((D44+G44)*E44)/10000 -> 0 | L44: =K44*B44 -> 0
A45: =+A44+1 -> 11 | K45: =((D45+G45)*E45)/10000 -> 0 | L45: =K45*B45 -> 0
...

Sheet 4. EQ. ADIC. "C"
D1: LISTA DE EMPAQUE PARA ÁREAS | H1: No. | N1: EQUIPO MUROS | P1: EQUIPO LOSA | R1: EQUIPO UNION MURO LOSA | T1: EQUIPO CULATAS
K2: AREA TOTAL | N2: ANGULOS PARA MUROS | O2: =+$B20 -> 0 | P2: ANGULOS PARA LOSA | Q2: =+$B31 -> 0 | R2: EQL | S2: =+$B283 -> 0 | T2: ESQUINEROS EQMT | U2: =+$B94 -> 0
K3: =+$O$9+$Q$9+$S$3+$U$9+$S$9 -> 0 | N3: ESQUINEROS DE MURO | O3: =+$B52 -> 0 | P3: ESQUINEROS DE MURO C/TAPA | Q3: =+$B73 -> 0 | R3: SUBTOTAL | S3: =SUM($S$2) -> 0 | T3: EQL CON PENDIENTE | U3: =+$B304 -> 0
N4: FORMALETAS DE MURO | O4: =+$B115 -> 0 | P4: FORMALETA DE LOSA, FLP (SON 3) | Q4: =+$B157 -> 0 | R4: PRETIL | T4: CULATAS | U4: =+$B325 -> 0
N5: TAPAS, TAPA PUNTAL (SON 3) | O5: =+$B136 -> 0 | P5: CAPS / BORDE DE LOSA | Q5: =+$B178 -> 0 | R5: CAPS PRETIL | S5: =+$B199 -> 0 | T5: CULATAS CUMBRERA | U5: =+$B346 -> 0
A6: CLIENTE: | F6: ELABORADO POR: | R6: CAPS PRETIL C/PENDIENTE | S6: =+$B220 -> 0 | T6: CULATÓN | U6: =+$B367 -> 0
A7: PROYECTO: | F7: FECHA: | R7: EQMP | S7: =+$B241 -> 0 | T7: CULATÓN CUMBRERA | U7: =+$B388 -> 0
A8: REFERENCIA: | C8: 4. EQ. ADIC. "C" | R8: EQMP C/PENDIENTE | S8: =+$B242 -> 0
N9: SUBTOTAL | O9: =SUM($O$2:$O$5) -> 0 | P9: SUBTOTAL | Q9: =SUM($Q$2:$Q$5) -> 0 | R9: SUBTOTAL | S9: =SUM($S$5:$S$8) -> 0 | T9: SUBTOTAL | U9: =SUM($U$2:$U$7) -> 0
A11: ÁNGULOS PARA MUROS (AG) | I11: MUROS
A12: ITEM | B12: CAN. | C12: DESCRIPCION | D12: ANC1 | E12: ALT1 | F12: ALT2 | G12: ANC2 | H12: OBSERVACIONES
A13: 1 | K13: =((D13+G13)*E13)/10000 -> 0 | L13: =K13*B13 -> 0
A14: =+A13+1 -> 2 | K14: =((D14+G14)*E14)/10000 -> 0 | L14: =K14*B14 -> 0
A15: =+A14+1 -> 3 | K15: =((D15+G15)*E15)/10000 -> 0 | L15: =K15*B15 -> 0
A16: =+A15+1 -> 4 | K16: =((D16+G16)*E16)/10000 -> 0 | L16: =K16*B16 -> 0
A17: =+A16+1 -> 5 | K17: =((D17+G17)*E17)/10000 -> 0 | L17: =K17*B17 -> 0
B19: =SUM(B13:B18) -> 0 | C19: TOTAL ÁNGULOS PARA MUROS | L19: =SUM(L13:L18) -> 0
B20: =+$L19 -> 0 | C20: TOTAL M²
A22: ÁNGULOS PARA LOSA (AG) | I22: LOSA
A23: ITEM | B23: CAN. | C23: DESCRIPCION | D23: ANC1 | E23: ALT1 | F23: ALT2 | G23: ANC2 | H23: OBSERVACIONES
A24: 1 | K24: =((D24+G24)*E24)/10000 -> 0 | L24: =K24*B24 -> 0
A25: =+A24+1 -> 2 | K25: =((D25+G25)*E25)/10000 -> 0 | L25: =K25*B25 -> 0
A26: =+A25+1 -> 3 | K26: =((D26+G26)*E26)/10000 -> 0 | L26: =K26*B26 -> 0
A27: =+A26+1 -> 4 | K27: =((D27+G27)*E27)/10000 -> 0 | L27: =K27*B27 -> 0
A28: =+A27+1 -> 5 | K28: =((D28+G28)*E28)/10000 -> 0 | L28: =K28*B28 -> 0
B30: =SUM(B24:B29) -> 0 | C30: TOTAL ÁNGULOS PARA LOSA | L30: =SUM(L24:L29) -> 0
B31: =+$L30 -> 0 | C31: TOTAL M²
A33: ESQUINEROS DE MURO (EQM) | I33: MUROS
A34: ITEM | B34: CAN. | C34: DESCRIPCION | D34: ANC1 | E34: ALT1 | F34: ALT2 | G34: ANC2 | H34: OBSERVACIONES
A35: 1 | K35: =((D35+G35)*E35)/10000 -> 0 | L35: =K35*B35 -> 0
A36: =+A35+1 -> 2 | K36: =((D36+G36)*E36)/10000 -> 0 | L36: =K36*B36 -> 0
A37: =+A36+1 -> 3 | K37: =((D37+G37)*E37)/10000 -> 0 | L37: =K37*B37 -> 0
A38: =+A37+1 -> 4 | K38: =((D38+G38)*E38)/10000 -> 0 | L38: =K38*B38 -> 0
A39: =+A38+1 -> 5 | K39: =((D39+G39)*E39)/10000 -> 0 | L39: =K39*B39 -> 0
A40: =+A39+1 -> 6 | K40: =((D40+G40)*E40)/10000 -> 0 | L40: =K40*B40 -> 0
A41: =+A40+1 -> 7 | K41: =((D41+G41)*E41)/10000 -> 0 | L41: =K41*B41 -> 0
A42: =+A41+1 -> 8 | K42: =((D42+G42)*E42)/10000 -> 0 | L42: =K42*B42 -> 0
A43: =+A42+1 -> 9 | K43: =((D43+G43)*E43)/10000 -> 0 | L43: =K43*B43 -> 0
A44: =+A43+1 -> 10 | K44: =((D44+G44)*E44)/10000 -> 0 | L44: =K44*B44 -> 0
A45: =+A44+1 -> 11 | K45: =((D45+G45)*E45)/10000 -> 0 | L45: =K45*B45 -> 0
...

Sheet 5. EQ. ADIC. "D"
D1: LISTA DE EMPAQUE PARA ÁREAS | H1: No. | N1: EQUIPO MUROS | P1: EQUIPO LOSA | R1: EQUIPO UNION MURO LOSA | T1: EQUIPO CULATAS
K2: AREA TOTAL | N2: ANGULOS PARA MUROS | O2: =+$B20 -> 0 | P2: ANGULOS PARA LOSA | Q2: =+$B31 -> 0 | R2: EQL | S2: =+$B283 -> 0 | T2: ESQUINEROS EQMT | U2: =+$B94 -> 0
K3: =+$O$9+$Q$9+$S$3+$U$9+$S$9 -> 0 | N3: ESQUINEROS DE MURO | O3: =+$B52 -> 0 | P3: ESQUINEROS DE MURO C/TAPA | Q3: =+$B73 -> 0 | R3: SUBTOTAL | S3: =SUM($S$2) -> 0 | T3: EQL CON PENDIENTE | U3: =+$B304 -> 0
N4: FORMALETAS DE MURO | O4: =+$B115 -> 0 | P4: FORMALETA DE LOSA, FLP (SON 3) | Q4: =+$B157 -> 0 | R4: PRETIL | T4: CULATAS | U4: =+$B325 -> 0
N5: TAPAS, TAPA PUNTAL (SON 3) | O5: =+$B136 -> 0 | P5: CAPS / BORDE DE LOSA | Q5: =+$B178 -> 0 | R5: CAPS PRETIL | S5: =+$B199 -> 0 | T5: CULATAS CUMBRERA | U5: =+$B346 -> 0
A6: CLIENTE: | F6: ELABORADO POR: | R6: CAPS PRETIL C/PENDIENTE | S6: =+$B220 -> 0 | T6: CULATÓN | U6: =+$B367 -> 0
A7: PROYECTO: | F7: FECHA: | R7: EQMP | S7: =+$B241 -> 0 | T7: CULATÓN CUMBRERA | U7: =+$B388 -> 0
A8: REFERENCIA: | C8: 5. EQ. ADIC. "D" | R8: EQMP C/PENDIENTE | S8: =+$B242 -> 0
N9: SUBTOTAL | O9: =SUM($O$2:$O$5) -> 0 | P9: SUBTOTAL | Q9: =SUM($Q$2:$Q$5) -> 0 | R9: SUBTOTAL | S9: =SUM($S$5:$S$8) -> 0 | T9: SUBTOTAL | U9: =SUM($U$2:$U$7) -> 0
A11: ÁNGULOS PARA MUROS (AG) | I11: MUROS
A12: ITEM | B12: CAN. | C12: DESCRIPCION | D12: ANC1 | E12: ALT1 | F12: ALT2 | G12: ANC2 | H12: OBSERVACIONES
A13: 1 | K13: =((D13+G13)*E13)/10000 -> 0 | L13: =K13*B13 -> 0
A14: =+A13+1 -> 2 | K14: =((D14+G14)*E14)/10000 -> 0 | L14: =K14*B14 -> 0
A15: =+A14+1 -> 3 | K15: =((D15+G15)*E15)/10000 -> 0 | L15: =K15*B15 -> 0
A16: =+A15+1 -> 4 | K16: =((D16+G16)*E16)/10000 -> 0 | L16: =K16*B16 -> 0
A17: =+A16+1 -> 5 | K17: =((D17+G17)*E17)/10000 -> 0 | L17: =K17*B17 -> 0
B19: =SUM(B13:B18) -> 0 | C19: TOTAL ÁNGULOS PARA MUROS | L19: =SUM(L13:L18) -> 0
B20: =+$L19 -> 0 | C20: TOTAL M²
A22: ÁNGULOS PARA LOSA (AG) | I22: LOSA
A23: ITEM | B23: CAN. | C23: DESCRIPCION | D23: ANC1 | E23: ALT1 | F23: ALT2 | G23: ANC2 | H23: OBSERVACIONES
A24: 1 | K24: =((D24+G24)*E24)/10000 -> 0 | L24: =K24*B24 -> 0
A25: =+A24+1 -> 2 | K25: =((D25+G25)*E25)/10000 -> 0 | L25: =K25*B25 -> 0
A26: =+A25+1 -> 3 | K26: =((D26+G26)*E26)/10000 -> 0 | L26: =K26*B26 -> 0
A27: =+A26+1 -> 4 | K27: =((D27+G27)*E27)/10000 -> 0 | L27: =K27*B27 -> 0
A28: =+A27+1 -> 5 | K28: =((D28+G28)*E28)/10000 -> 0 | L28: =K28*B28 -> 0
B30: =SUM(B24:B29) -> 0 | C30: TOTAL ÁNGULOS PARA LOSA | L30: =SUM(L24:L29) -> 0
B31: =+$L30 -> 0 | C31: TOTAL M²
A33: ESQUINEROS DE MURO (EQM) | I33: MUROS
A34: ITEM | B34: CAN. | C34: DESCRIPCION | D34: ANC1 | E34: ALT1 | F34: ALT2 | G34: ANC2 | H34: OBSERVACIONES
A35: 1 | K35: =((D35+G35)*E35)/10000 -> 0 | L35: =K35*B35 -> 0
A36: =+A35+1 -> 2 | K36: =((D36+G36)*E36)/10000 -> 0 | L36: =K36*B36 -> 0
A37: =+A36+1 -> 3 | K37: =((D37+G37)*E37)/10000 -> 0 | L37: =K37*B37 -> 0
A38: =+A37+1 -> 4 | K38: =((D38+G38)*E38)/10000 -> 0 | L38: =K38*B38 -> 0
A39: =+A38+1 -> 5 | K39: =((D39+G39)*E39)/10000 -> 0 | L39: =K39*B39 -> 0
A40: =+A39+1 -> 6 | K40: =((D40+G40)*E40)/10000 -> 0 | L40: =K40*B40 -> 0
A41: =+A40+1 -> 7 | K41: =((D41+G41)*E41)/10000 -> 0 | L41: =K41*B41 -> 0
A42: =+A41+1 -> 8 | K42: =((D42+G42)*E42)/10000 -> 0 | L42: =K42*B42 -> 0
A43: =+A42+1 -> 9 | K43: =((D43+G43)*E43)/10000 -> 0 | L43: =K43*B43 -> 0
A44: =+A43+1 -> 10 | K44: =((D44+G44)*E44)/10000 -> 0 | L44: =K44*B44 -> 0
A45: =+A44+1 -> 11 | K45: =((D45+G45)*E45)/10000 -> 0 | L45: =K45*B45 -> 0
...

Sheet 6. EQ. ADIC. "E"
D1: LISTA DE EMPAQUE PARA ÁREAS | H1: No. | N1: EQUIPO MUROS | P1: EQUIPO LOSA | R1: EQUIPO UNION MURO LOSA | T1: EQUIPO CULATAS
K2: AREA TOTAL | N2: ANGULOS PARA MUROS | O2: =+$B20 -> 0 | P2: ANGULOS PARA LOSA | Q2: =+$B31 -> 0 | R2: EQL | S2: =+$B283 -> 0 | T2: ESQUINEROS EQMT | U2: =+$B94 -> 0
K3: =+$O$9+$Q$9+$S$3+$U$9+$S$9 -> 0 | N3: ESQUINEROS DE MURO | O3: =+$B52 -> 0 | P3: ESQUINEROS DE MURO C/TAPA | Q3: =+$B73 -> 0 | R3: SUBTOTAL | S3: =SUM($S$2) -> 0 | T3: EQL CON PENDIENTE | U3: =+$B304 -> 0
N4: FORMALETAS DE MURO | O4: =+$B115 -> 0 | P4: FORMALETA DE LOSA, FLP (SON 3) | Q4: =+$B157 -> 0 | R4: PRETIL | T4: CULATAS | U4: =+$B325 -> 0
N5: TAPAS, TAPA PUNTAL (SON 3) | O5: =+$B136 -> 0 | P5: CAPS / BORDE DE LOSA | Q5: =+$B178 -> 0 | R5: CAPS PRETIL | S5: =+$B199 -> 0 | T5: CULATAS CUMBRERA | U5: =+$B346 -> 0
A6: CLIENTE: | F6: ELABORADO POR: | R6: CAPS PRETIL C/PENDIENTE | S6: =+$B220 -> 0 | T6: CULATÓN | U6: =+$B367 -> 0
A7: PROYECTO: | F7: FECHA: | R7: EQMP | S7: =+$B241 -> 0 | T7: CULATÓN CUMBRERA | U7: =+$B388 -> 0
A8: REFERENCIA: | C8: 6. EQ. ADIC. "E" | R8: EQMP C/PENDIENTE | S8: =+$B242 -> 0
N9: SUBTOTAL | O9: =SUM($O$2:$O$5) -> 0 | P9: SUBTOTAL | Q9: =SUM($Q$2:$Q$5) -> 0 | R9: SUBTOTAL | S9: =SUM($S$5:$S$8) -> 0 | T9: SUBTOTAL | U9: =SUM($U$2:$U$7) -> 0
A11: ÁNGULOS PARA MUROS (AG) | I11: MUROS
A12: ITEM | B12: CAN. | C12: DESCRIPCION | D12: ANC1 | E12: ALT1 | F12: ALT2 | G12: ANC2 | H12: OBSERVACIONES
A13: 1 | K13: =((D13+G13)*E13)/10000 -> 0 | L13: =K13*B13 -> 0
A14: =+A13+1 -> 2 | K14: =((D14+G14)*E14)/10000 -> 0 | L14: =K14*B14 -> 0
A15: =+A14+1 -> 3 | K15: =((D15+G15)*E15)/10000 -> 0 | L15: =K15*B15 -> 0
A16: =+A15+1 -> 4 | K16: =((D16+G16)*E16)/10000 -> 0 | L16: =K16*B16 -> 0
A17: =+A16+1 -> 5 | K17: =((D17+G17)*E17)/10000 -> 0 | L17: =K17*B17 -> 0
B19: =SUM(B13:B18) -> 0 | C19: TOTAL ÁNGULOS PARA MUROS | L19: =SUM(L13:L18) -> 0
B20: =+$L19 -> 0 | C20: TOTAL M²
A22: ÁNGULOS PARA LOSA (AG) | I22: LOSA
A23: ITEM | B23: CAN. | C23: DESCRIPCION | D23: ANC1 | E23: ALT1 | F23: ALT2 | G23: ANC2 | H23: OBSERVACIONES
A24: 1 | K24: =((D24+G24)*E24)/10000 -> 0 | L24: =K24*B24 -> 0
A25: =+A24+1 -> 2 | K25: =((D25+G25)*E25)/10000 -> 0 | L25: =K25*B25 -> 0
A26: =+A25+1 -> 3 | K26: =((D26+G26)*E26)/10000 -> 0 | L26: =K26*B26 -> 0
A27: =+A26+1 -> 4 | K27: =((D27+G27)*E27)/10000 -> 0 | L27: =K27*B27 -> 0
A28: =+A27+1 -> 5 | K28: =((D28+G28)*E28)/10000 -> 0 | L28: =K28*B28 -> 0
B30: =SUM(B24:B29) -> 0 | C30: TOTAL ÁNGULOS PARA LOSA | L30: =SUM(L24:L29) -> 0
B31: =+$L30 -> 0 | C31: TOTAL M²
A33: ESQUINEROS DE MURO (EQM) | I33: MUROS
A34: ITEM | B34: CAN. | C34: DESCRIPCION | D34: ANC1 | E34: ALT1 | F34: ALT2 | G34: ANC2 | H34: OBSERVACIONES
A35: 1 | K35: =((D35+G35)*E35)/10000 -> 0 | L35: =K35*B35 -> 0
A36: =+A35+1 -> 2 | K36: =((D36+G36)*E36)/10000 -> 0 | L36: =K36*B36 -> 0
A37: =+A36+1 -> 3 | K37: =((D37+G37)*E37)/10000 -> 0 | L37: =K37*B37 -> 0
A38: =+A37+1 -> 4 | K38: =((D38+G38)*E38)/10000 -> 0 | L38: =K38*B38 -> 0
A39: =+A38+1 -> 5 | K39: =((D39+G39)*E39)/10000 -> 0 | L39: =K39*B39 -> 0
A40: =+A39+1 -> 6 | K40: =((D40+G40)*E40)/10000 -> 0 | L40: =K40*B40 -> 0
A41: =+A40+1 -> 7 | K41: =((D41+G41)*E41)/10000 -> 0 | L41: =K41*B41 -> 0
A42: =+A41+1 -> 8 | K42: =((D42+G42)*E42)/10000 -> 0 | L42: =K42*B42 -> 0
A43: =+A42+1 -> 9 | K43: =((D43+G43)*E43)/10000 -> 0 | L43: =K43*B43 -> 0
A44: =+A43+1 -> 10 | K44: =((D44+G44)*E44)/10000 -> 0 | L44: =K44*B44 -> 0
A45: =+A44+1 -> 11 | K45: =((D45+G45)*E45)/10000 -> 0 | L45: =K45*B45 -> 0
...

Sheet 7. EQ. ADIC. "F"
D1: LISTA DE EMPAQUE PARA ÁREAS | H1: No. | N1: EQUIPO MUROS | P1: EQUIPO LOSA | R1: EQUIPO UNION MURO LOSA | T1: EQUIPO CULATAS
K2: AREA TOTAL | N2: ANGULOS PARA MUROS | O2: =+$B20 -> 0 | P2: ANGULOS PARA LOSA | Q2: =+$B31 -> 0 | R2: EQL | S2: =+$B283 -> 0 | T2: ESQUINEROS EQMT | U2: =+$B94 -> 0
K3: =+$O$9+$Q$9+$S$3+$U$9+$S$9 -> 0 | N3: ESQUINEROS DE MURO | O3: =+$B52 -> 0 | P3: ESQUINEROS DE MURO C/TAPA | Q3: =+$B73 -> 0 | R3: SUBTOTAL | S3: =SUM($S$2) -> 0 | T3: EQL CON PENDIENTE | U3: =+$B304 -> 0
N4: FORMALETAS DE MURO | O4: =+$B115 -> 0 | P4: FORMALETA DE LOSA, FLP (SON 3) | Q4: =+$B157 -> 0 | R4: PRETIL | T4: CULATAS | U4: =+$B325 -> 0
N5: TAPAS, TAPA PUNTAL (SON 3) | O5: =+$B136 -> 0 | P5: CAPS / BORDE DE LOSA | Q5: =+$B178 -> 0 | R5: CAPS PRETIL | S5: =+$B199 -> 0 | T5: CULATAS CUMBRERA | U5: =+$B346 -> 0
A6: CLIENTE: | F6: ELABORADO POR: | R6: CAPS PRETIL C/PENDIENTE | S6: =+$B220 -> 0 | T6: CULATÓN | U6: =+$B367 -> 0
A7: PROYECTO: | F7: FECHA: | R7: EQMP | S7: =+$B241 -> 0 | T7: CULATÓN CUMBRERA | U7: =+$B388 -> 0
A8: REFERENCIA: | C8: 7. EQ. ADIC. "F" | R8: EQMP C/PENDIENTE | S8: =+$B242 -> 0
N9: SUBTOTAL | O9: =SUM($O$2:$O$5) -> 0 | P9: SUBTOTAL | Q9: =SUM($Q$2:$Q$5) -> 0 | R9: SUBTOTAL | S9: =SUM($S$5:$S$8) -> 0 | T9: SUBTOTAL | U9: =SUM($U$2:$U$7) -> 0
A11: ÁNGULOS PARA MUROS (AG) | I11: MUROS
A12: ITEM | B12: CAN. | C12: DESCRIPCION | D12: ANC1 | E12: ALT1 | F12: ALT2 | G12: ANC2 | H12: OBSERVACIONES
A13: 1 | K13: =((D13+G13)*E13)/10000 -> 0 | L13: =K13*B13 -> 0
A14: =+A13+1 -> 2 | K14: =((D14+G14)*E14)/10000 -> 0 | L14: =K14*B14 -> 0
A15: =+A14+1 -> 3 | K15: =((D15+G15)*E15)/10000 -> 0 | L15: =K15*B15 -> 0
A16: =+A15+1 -> 4 | K16: =((D16+G16)*E16)/10000 -> 0 | L16: =K16*B16 -> 0
A17: =+A16+1 -> 5 | K17: =((D17+G17)*E17)/10000 -> 0 | L17: =K17*B17 -> 0
B19: =SUM(B13:B18) -> 0 | C19: TOTAL ÁNGULOS PARA MUROS | L19: =SUM(L13:L18) -> 0
B20: =+$L19 -> 0 | C20: TOTAL M²
A22: ÁNGULOS PARA LOSA (AG) | I22: LOSA
A23: ITEM | B23: CAN. | C23: DESCRIPCION | D23: ANC1 | E23: ALT1 | F23: ALT2 | G23: ANC2 | H23: OBSERVACIONES
A24: 1 | K24: =((D24+G24)*E24)/10000 -> 0 | L24: =K24*B24 -> 0
A25: =+A24+1 -> 2 | K25: =((D25+G25)*E25)/10000 -> 0 | L25: =K25*B25 -> 0
A26: =+A25+1 -> 3 | K26: =((D26+G26)*E26)/10000 -> 0 | L26: =K26*B26 -> 0
A27: =+A26+1 -> 4 | K27: =((D27+G27)*E27)/10000 -> 0 | L27: =K27*B27 -> 0
A28: =+A27+1 -> 5 | K28: =((D28+G28)*E28)/10000 -> 0 | L28: =K28*B28 -> 0
B30: =SUM(B24:B29) -> 0 | C30: TOTAL ÁNGULOS PARA LOSA | L30: =SUM(L24:L29) -> 0
B31: =+$L30 -> 0 | C31: TOTAL M²
A33: ESQUINEROS DE MURO (EQM) | I33: MUROS
A34: ITEM | B34: CAN. | C34: DESCRIPCION | D34: ANC1 | E34: ALT1 | F34: ALT2 | G34: ANC2 | H34: OBSERVACIONES
A35: 1 | K35: =((D35+G35)*E35)/10000 -> 0 | L35: =K35*B35 -> 0
A36: =+A35+1 -> 2 | K36: =((D36+G36)*E36)/10000 -> 0 | L36: =K36*B36 -> 0
A37: =+A36+1 -> 3 | K37: =((D37+G37)*E37)/10000 -> 0 | L37: =K37*B37 -> 0
A38: =+A37+1 -> 4 | K38: =((D38+G38)*E38)/10000 -> 0 | L38: =K38*B38 -> 0
A39: =+A38+1 -> 5 | K39: =((D39+G39)*E39)/10000 -> 0 | L39: =K39*B39 -> 0
A40: =+A39+1 -> 6 | K40: =((D40+G40)*E40)/10000 -> 0 | L40: =K40*B40 -> 0
A41: =+A40+1 -> 7 | K41: =((D41+G41)*E41)/10000 -> 0 | L41: =K41*B41 -> 0
A42: =+A41+1 -> 8 | K42: =((D42+G42)*E42)/10000 -> 0 | L42: =K42*B42 -> 0
A43: =+A42+1 -> 9 | K43: =((D43+G43)*E43)/10000 -> 0 | L43: =K43*B43 -> 0
A44: =+A43+1 -> 10 | K44: =((D44+G44)*E44)/10000 -> 0 | L44: =K44*B44 -> 0
A45: =+A44+1 -> 11 | K45: =((D45+G45)*E45)/10000 -> 0 | L45: =K45*B45 -> 0
...

Sheet 8. EQ. ADIC. "G"
D1: LISTA DE EMPAQUE PARA ÁREAS | H1: No. | N1: EQUIPO MUROS | P1: EQUIPO LOSA | R1: EQUIPO UNION MURO LOSA | T1: EQUIPO CULATAS
K2: AREA TOTAL | N2: ANGULOS PARA MUROS | O2: =+$B20 -> 0 | P2: ANGULOS PARA LOSA | Q2: =+$B31 -> 0 | R2: EQL | S2: =+$B283 -> 0 | T2: ESQUINEROS EQMT | U2: =+$B94 -> 0
K3: =+$O$9+$Q$9+$S$3+$U$9+$S$9 -> 0 | N3: ESQUINEROS DE MURO | O3: =+$B52 -> 0 | P3: ESQUINEROS DE MURO C/TAPA | Q3: =+$B73 -> 0 | R3: SUBTOTAL | S3: =SUM($S$2) -> 0 | T3: EQL CON PENDIENTE | U3: =+$B304 -> 0
N4: FORMALETAS DE MURO | O4: =+$B115 -> 0 | P4: FORMALETA DE LOSA, FLP (SON 3) | Q4: =+$B157 -> 0 | R4: PRETIL | T4: CULATAS | U4: =+$B325 -> 0
N5: TAPAS, TAPA PUNTAL (SON 3) | O5: =+$B136 -> 0 | P5: CAPS / BORDE DE LOSA | Q5: =+$B178 -> 0 | R5: CAPS PRETIL | S5: =+$B199 -> 0 | T5: CULATAS CUMBRERA | U5: =+$B346 -> 0
A6: CLIENTE: | F6: ELABORADO POR: | R6: CAPS PRETIL C/PENDIENTE | S6: =+$B220 -> 0 | T6: CULATÓN | U6: =+$B367 -> 0
A7: PROYECTO: | F7: FECHA: | R7: EQMP | S7: =+$B241 -> 0 | T7: CULATÓN CUMBRERA | U7: =+$B388 -> 0
A8: REFERENCIA: | C8: 8. EQ. ADIC. "G" | R8: EQMP C/PENDIENTE | S8: =+$B242 -> 0
N9: SUBTOTAL | O9: =SUM($O$2:$O$5) -> 0 | P9: SUBTOTAL | Q9: =SUM($Q$2:$Q$5) -> 0 | R9: SUBTOTAL | S9: =SUM($S$5:$S$8) -> 0 | T9: SUBTOTAL | U9: =SUM($U$2:$U$7) -> 0
A11: ÁNGULOS PARA MUROS (AG) | I11: MUROS
A12: ITEM | B12: CAN. | C12: DESCRIPCION | D12: ANC1 | E12: ALT1 | F12: ALT2 | G12: ANC2 | H12: OBSERVACIONES
A13: 1 | K13: =((D13+G13)*E13)/10000 -> 0 | L13: =K13*B13 -> 0
A14: =+A13+1 -> 2 | K14: =((D14+G14)*E14)/10000 -> 0 | L14: =K14*B14 -> 0
A15: =+A14+1 -> 3 | K15: =((D15+G15)*E15)/10000 -> 0 | L15: =K15*B15 -> 0
A16: =+A15+1 -> 4 | K16: =((D16+G16)*E16)/10000 -> 0 | L16: =K16*B16 -> 0
A17: =+A16+1 -> 5 | K17: =((D17+G17)*E17)/10000 -> 0 | L17: =K17*B17 -> 0
B19: =SUM(B13:B18) -> 0 | C19: TOTAL ÁNGULOS PARA MUROS | L19: =SUM(L13:L18) -> 0
B20: =+$L19 -> 0 | C20: TOTAL M²
A22: ÁNGULOS PARA LOSA (AG) | I22: LOSA
A23: ITEM | B23: CAN. | C23: DESCRIPCION | D23: ANC1 | E23: ALT1 | F23: ALT2 | G23: ANC2 | H23: OBSERVACIONES
A24: 1 | K24: =((D24+G24)*E24)/10000 -> 0 | L24: =K24*B24 -> 0
A25: =+A24+1 -> 2 | K25: =((D25+G25)*E25)/10000 -> 0 | L25: =K25*B25 -> 0
A26: =+A25+1 -> 3 | K26: =((D26+G26)*E26)/10000 -> 0 | L26: =K26*B26 -> 0
A27: =+A26+1 -> 4 | K27: =((D27+G27)*E27)/10000 -> 0 | L27: =K27*B27 -> 0
A28: =+A27+1 -> 5 | K28: =((D28+G28)*E28)/10000 -> 0 | L28: =K28*B28 -> 0
B30: =SUM(B24:B29) -> 0 | C30: TOTAL ÁNGULOS PARA LOSA | L30: =SUM(L24:L29) -> 0
B31: =+$L30 -> 0 | C31: TOTAL M²
A33: ESQUINEROS DE MURO (EQM) | I33: MUROS
A34: ITEM | B34: CAN. | C34: DESCRIPCION | D34: ANC1 | E34: ALT1 | F34: ALT2 | G34: ANC2 | H34: OBSERVACIONES
A35: 1 | K35: =((D35+G35)*E35)/10000 -> 0 | L35: =K35*B35 -> 0
A36: =+A35+1 -> 2 | K36: =((D36+G36)*E36)/10000 -> 0 | L36: =K36*B36 -> 0
A37: =+A36+1 -> 3 | K37: =((D37+G37)*E37)/10000 -> 0 | L37: =K37*B37 -> 0
A38: =+A37+1 -> 4 | K38: =((D38+G38)*E38)/10000 -> 0 | L38: =K38*B38 -> 0
A39: =+A38+1 -> 5 | K39: =((D39+G39)*E39)/10000 -> 0 | L39: =K39*B39 -> 0
A40: =+A39+1 -> 6 | K40: =((D40+G40)*E40)/10000 -> 0 | L40: =K40*B40 -> 0
A41: =+A40+1 -> 7 | K41: =((D41+G41)*E41)/10000 -> 0 | L41: =K41*B41 -> 0
A42: =+A41+1 -> 8 | K42: =((D42+G42)*E42)/10000 -> 0 | L42: =K42*B42 -> 0
A43: =+A42+1 -> 9 | K43: =((D43+G43)*E43)/10000 -> 0 | L43: =K43*B43 -> 0
A44: =+A43+1 -> 10 | K44: =((D44+G44)*E44)/10000 -> 0 | L44: =K44*B44 -> 0
A45: =+A44+1 -> 11 | K45: =((D45+G45)*E45)/10000 -> 0 | L45: =K45*B45 -> 0
...

Sheet 9. EQ. ADIC. "H"
D1: LISTA DE EMPAQUE PARA ÁREAS | H1: No. | N1: EQUIPO MUROS | P1: EQUIPO LOSA | R1: EQUIPO UNION MURO LOSA | T1: EQUIPO CULATAS
K2: AREA TOTAL | N2: ANGULOS PARA MUROS | O2: =+$B20 -> 0 | P2: ANGULOS PARA LOSA | Q2: =+$B31 -> 0 | R2: EQL | S2: =+$B283 -> 0 | T2: ESQUINEROS EQMT | U2: =+$B94 -> 0
K3: =+$O$9+$Q$9+$S$3+$U$9+$S$9 -> 0 | N3: ESQUINEROS DE MURO | O3: =+$B52 -> 0 | P3: ESQUINEROS DE MURO C/TAPA | Q3: =+$B73 -> 0 | R3: SUBTOTAL | S3: =SUM($S$2) -> 0 | T3: EQL CON PENDIENTE | U3: =+$B304 -> 0
N4: FORMALETAS DE MURO | O4: =+$B115 -> 0 | P4: FORMALETA DE LOSA, FLP (SON 3) | Q4: =+$B157 -> 0 | R4: PRETIL | T4: CULATAS | U4: =+$B325 -> 0
N5: TAPAS, TAPA PUNTAL (SON 3) | O5: =+$B136 -> 0 | P5: CAPS / BORDE DE LOSA | Q5: =+$B178 -> 0 | R5: CAPS PRETIL | S5: =+$B199 -> 0 | T5: CULATAS CUMBRERA | U5: =+$B346 -> 0
A6: CLIENTE: | F6: ELABORADO POR: | R6: CAPS PRETIL C/PENDIENTE | S6: =+$B220 -> 0 | T6: CULATÓN | U6: =+$B367 -> 0
A7: PROYECTO: | F7: FECHA: | R7: EQMP | S7: =+$B241 -> 0 | T7: CULATÓN CUMBRERA | U7: =+$B388 -> 0
A8: REFERENCIA: | C8: 9. EQ. ADIC. "H" | R8: EQMP C/PENDIENTE | S8: =+$B242 -> 0
N9: SUBTOTAL | O9: =SUM($O$2:$O$5) -> 0 | P9: SUBTOTAL | Q9: =SUM($Q$2:$Q$5) -> 0 | R9: SUBTOTAL | S9: =SUM($S$5:$S$8) -> 0 | T9: SUBTOTAL | U9: =SUM($U$2:$U$7) -> 0
A11: ÁNGULOS PARA MUROS (AG) | I11: MUROS
A12: ITEM | B12: CAN. | C12: DESCRIPCION | D12: ANC1 | E12: ALT1 | F12: ALT2 | G12: ANC2 | H12: OBSERVACIONES
A13: 1 | K13: =((D13+G13)*E13)/10000 -> 0 | L13: =K13*B13 -> 0
A14: =+A13+1 -> 2 | K14: =((D14+G14)*E14)/10000 -> 0 | L14: =K14*B14 -> 0
A15: =+A14+1 -> 3 | K15: =((D15+G15)*E15)/10000 -> 0 | L15: =K15*B15 -> 0
A16: =+A15+1 -> 4 | K16: =((D16+G16)*E16)/10000 -> 0 | L16: =K16*B16 -> 0
A17: =+A16+1 -> 5 | K17: =((D17+G17)*E17)/10000 -> 0 | L17: =K17*B17 -> 0
B19: =SUM(B13:B18) -> 0 | C19: TOTAL ÁNGULOS PARA MUROS | L19: =SUM(L13:L18) -> 0
B20: =+$L19 -> 0 | C20: TOTAL M²
A22: ÁNGULOS PARA LOSA (AG) | I22: LOSA
A23: ITEM | B23: CAN. | C23: DESCRIPCION | D23: ANC1 | E23: ALT1 | F23: ALT2 | G23: ANC2 | H23: OBSERVACIONES
A24: 1 | K24: =((D24+G24)*E24)/10000 -> 0 | L24: =K24*B24 -> 0
A25: =+A24+1 -> 2 | K25: =((D25+G25)*E25)/10000 -> 0 | L25: =K25*B25 -> 0
A26: =+A25+1 -> 3 | K26: =((D26+G26)*E26)/10000 -> 0 | L26: =K26*B26 -> 0
A27: =+A26+1 -> 4 | K27: =((D27+G27)*E27)/10000 -> 0 | L27: =K27*B27 -> 0
A28: =+A27+1 -> 5 | K28: =((D28+G28)*E28)/10000 -> 0 | L28: =K28*B28 -> 0
B30: =SUM(B24:B29) -> 0 | C30: TOTAL ÁNGULOS PARA LOSA | L30: =SUM(L24:L29) -> 0
B31: =+$L30 -> 0 | C31: TOTAL M²
A33: ESQUINEROS DE MURO (EQM) | I33: MUROS
A34: ITEM | B34: CAN. | C34: DESCRIPCION | D34: ANC1 | E34: ALT1 | F34: ALT2 | G34: ANC2 | H34: OBSERVACIONES
A35: 1 | K35: =((D35+G35)*E35)/10000 -> 0 | L35: =K35*B35 -> 0
A36: =+A35+1 -> 2 | K36: =((D36+G36)*E36)/10000 -> 0 | L36: =K36*B36 -> 0
A37: =+A36+1 -> 3 | K37: =((D37+G37)*E37)/10000 -> 0 | L37: =K37*B37 -> 0
A38: =+A37+1 -> 4 | K38: =((D38+G38)*E38)/10000 -> 0 | L38: =K38*B38 -> 0
A39: =+A38+1 -> 5 | K39: =((D39+G39)*E39)/10000 -> 0 | L39: =K39*B39 -> 0
A40: =+A39+1 -> 6 | K40: =((D40+G40)*E40)/10000 -> 0 | L40: =K40*B40 -> 0
A41: =+A40+1 -> 7 | K41: =((D41+G41)*E41)/10000 -> 0 | L41: =K41*B41 -> 0
A42: =+A41+1 -> 8 | K42: =((D42+G42)*E42)/10000 -> 0 | L42: =K42*B42 -> 0
A43: =+A42+1 -> 9 | K43: =((D43+G43)*E43)/10000 -> 0 | L43: =K43*B43 -> 0
A44: =+A43+1 -> 10 | K44: =((D44+G44)*E44)/10000 -> 0 | L44: =K44*B44 -> 0
A45: =+A44+1 -> 11 | K45: =((D45+G45)*E45)/10000 -> 0 | L45: =K45*B45 -> 0
...

Sheet 10. EQ. ADIC. "I"
D1: LISTA DE EMPAQUE PARA ÁREAS | H1: No. | N1: EQUIPO MUROS | P1: EQUIPO LOSA | R1: EQUIPO UNION MURO LOSA | T1: EQUIPO CULATAS
K2: AREA TOTAL | N2: ANGULOS PARA MUROS | O2: =+$B20 -> 0 | P2: ANGULOS PARA LOSA | Q2: =+$B31 -> 0 | R2: EQL | S2: =+$B283 -> 0 | T2: ESQUINEROS EQMT | U2: =+$B94 -> 0
K3: =+$O$9+$Q$9+$S$3+$U$9+$S$9 -> 0 | N3: ESQUINEROS DE MURO | O3: =+$B52 -> 0 | P3: ESQUINEROS DE MURO C/TAPA | Q3: =+$B73 -> 0 | R3: SUBTOTAL | S3: =SUM($S$2) -> 0 | T3: EQL CON PENDIENTE | U3: =+$B304 -> 0
N4: FORMALETAS DE MURO | O4: =+$B115 -> 0 | P4: FORMALETA DE LOSA, FLP (SON 3) | Q4: =+$B157 -> 0 | R4: PRETIL | T4: CULATAS | U4: =+$B325 -> 0
N5: TAPAS, TAPA PUNTAL (SON 3) | O5: =+$B136 -> 0 | P5: CAPS / BORDE DE LOSA | Q5: =+$B178 -> 0 | R5: CAPS PRETIL | S5: =+$B199 -> 0 | T5: CULATAS CUMBRERA | U5: =+$B346 -> 0
A6: CLIENTE: | F6: ELABORADO POR: | R6: CAPS PRETIL C/PENDIENTE | S6: =+$B220 -> 0 | T6: CULATÓN | U6: =+$B367 -> 0
A7: PROYECTO: | F7: FECHA: | R7: EQMP | S7: =+$B241 -> 0 | T7: CULATÓN CUMBRERA | U7: =+$B388 -> 0
A8: REFERENCIA: | C8: 10. EQ. ADIC. "I" | R8: EQMP C/PENDIENTE | S8: =+$B242 -> 0
N9: SUBTOTAL | O9: =SUM($O$2:$O$5) -> 0 | P9: SUBTOTAL | Q9: =SUM($Q$2:$Q$5) -> 0 | R9: SUBTOTAL | S9: =SUM($S$5:$S$8) -> 0 | T9: SUBTOTAL | U9: =SUM($U$2:$U$7) -> 0
A11: ÁNGULOS PARA MUROS (AG) | I11: MUROS
A12: ITEM | B12: CAN. | C12: DESCRIPCION | D12: ANC1 | E12: ALT1 | F12: ALT2 | G12: ANC2 | H12: OBSERVACIONES
A13: 1 | K13: =((D13+G13)*E13)/10000 -> 0 | L13: =K13*B13 -> 0
A14: =+A13+1 -> 2 | K14: =((D14+G14)*E14)/10000 -> 0 | L14: =K14*B14 -> 0
A15: =+A14+1 -> 3 | K15: =((D15+G15)*E15)/10000 -> 0 | L15: =K15*B15 -> 0
A16: =+A15+1 -> 4 | K16: =((D16+G16)*E16)/10000 -> 0 | L16: =K16*B16 -> 0
A17: =+A16+1 -> 5 | K17: =((D17+G17)*E17)/10000 -> 0 | L17: =K17*B17 -> 0
B19: =SUM(B13:B18) -> 0 | C19: TOTAL ÁNGULOS PARA MUROS | L19: =SUM(L13:L18) -> 0
B20: =+$L19 -> 0 | C20: TOTAL M²
A22: ÁNGULOS PARA LOSA (AG) | I22: LOSA
A23: ITEM | B23: CAN. | C23: DESCRIPCION | D23: ANC1 | E23: ALT1 | F23: ALT2 | G23: ANC2 | H23: OBSERVACIONES
A24: 1 | K24: =((D24+G24)*E24)/10000 -> 0 | L24: =K24*B24 -> 0
A25: =+A24+1 -> 2 | K25: =((D25+G25)*E25)/10000 -> 0 | L25: =K25*B25 -> 0
A26: =+A25+1 -> 3 | K26: =((D26+G26)*E26)/10000 -> 0 | L26: =K26*B26 -> 0
A27: =+A26+1 -> 4 | K27: =((D27+G27)*E27)/10000 -> 0 | L27: =K27*B27 -> 0
A28: =+A27+1 -> 5 | K28: =((D28+G28)*E28)/10000 -> 0 | L28: =K28*B28 -> 0
B30: =SUM(B24:B29) -> 0 | C30: TOTAL ÁNGULOS PARA LOSA | L30: =SUM(L24:L29) -> 0
B31: =+$L30 -> 0 | C31: TOTAL M²
A33: ESQUINEROS DE MURO (EQM) | I33: MUROS
A34: ITEM | B34: CAN. | C34: DESCRIPCION | D34: ANC1 | E34: ALT1 | F34: ALT2 | G34: ANC2 | H34: OBSERVACIONES
A35: 1 | K35: =((D35+G35)*E35)/10000 -> 0 | L35: =K35*B35 -> 0
A36: =+A35+1 -> 2 | K36: =((D36+G36)*E36)/10000 -> 0 | L36: =K36*B36 -> 0
A37: =+A36+1 -> 3 | K37: =((D37+G37)*E37)/10000 -> 0 | L37: =K37*B37 -> 0
A38: =+A37+1 -> 4 | K38: =((D38+G38)*E38)/10000 -> 0 | L38: =K38*B38 -> 0
A39: =+A38+1 -> 5 | K39: =((D39+G39)*E39)/10000 -> 0 | L39: =K39*B39 -> 0
A40: =+A39+1 -> 6 | K40: =((D40+G40)*E40)/10000 -> 0 | L40: =K40*B40 -> 0
A41: =+A40+1 -> 7 | K41: =((D41+G41)*E41)/10000 -> 0 | L41: =K41*B41 -> 0
A42: =+A41+1 -> 8 | K42: =((D42+G42)*E42)/10000 -> 0 | L42: =K42*B42 -> 0
A43: =+A42+1 -> 9 | K43: =((D43+G43)*E43)/10000 -> 0 | L43: =K43*B43 -> 0
A44: =+A43+1 -> 10 | K44: =((D44+G44)*E44)/10000 -> 0 | L44: =K44*B44 -> 0
A45: =+A44+1 -> 11 | K45: =((D45+G45)*E45)/10000 -> 0 | L45: =K45*B45 -> 0
...
